# Watchtower — run from the north-west bottom corner.
# /function watchtower:watchtower
setblock ~0 ~0 ~9 minecraft:mossy_cobblestone
setblock ~0 ~0 ~10 minecraft:mossy_cobblestone
setblock ~0 ~0 ~11 minecraft:oak_leaves[distance=7,persistent=true]
setblock ~0 ~0 ~12 minecraft:mossy_cobblestone
setblock ~0 ~0 ~13 minecraft:mossy_cobblestone
setblock ~0 ~0 ~14 minecraft:stone_bricks
setblock ~0 ~0 ~15 minecraft:cobblestone
setblock ~0 ~1 ~10 minecraft:oak_leaves[distance=7,persistent=true]
setblock ~0 ~1 ~11 minecraft:oak_leaves[distance=7,persistent=true]
setblock ~0 ~1 ~12 minecraft:mossy_cobblestone
setblock ~0 ~1 ~13 minecraft:mossy_cobblestone
setblock ~0 ~1 ~14 minecraft:mossy_cobblestone
setblock ~0 ~1 ~15 minecraft:oak_leaves[distance=7,persistent=true]
setblock ~0 ~2 ~10 minecraft:oak_leaves[distance=7,persistent=true]
setblock ~0 ~2 ~11 minecraft:oak_leaves[distance=7,persistent=true]
setblock ~0 ~2 ~12 minecraft:oak_leaves[distance=7,persistent=true]
setblock ~0 ~2 ~13 minecraft:oak_leaves[distance=7,persistent=true]
setblock ~0 ~3 ~12 minecraft:oak_leaves[distance=7,persistent=true]
setblock ~0 ~3 ~13 minecraft:oak_leaves[distance=7,persistent=true]
setblock ~0 ~4 ~13 minecraft:oak_leaves[distance=7,persistent=true]
setblock ~0 ~4 ~14 minecraft:oak_leaves[distance=7,persistent=true]
setblock ~0 ~5 ~13 minecraft:oak_leaves[distance=7,persistent=true]
setblock ~0 ~5 ~14 minecraft:oak_leaves[distance=7,persistent=true]
setblock ~0 ~6 ~13 minecraft:oak_leaves[distance=7,persistent=true]
setblock ~0 ~6 ~14 minecraft:oak_leaves[distance=7,persistent=true]
setblock ~0 ~10 ~14 minecraft:oak_leaves[distance=7,persistent=true]
setblock ~0 ~12 ~10 minecraft:stone_bricks
setblock ~0 ~12 ~11 minecraft:cobblestone
setblock ~0 ~12 ~12 minecraft:stone_bricks
setblock ~0 ~12 ~13 minecraft:mossy_stone_bricks
setblock ~0 ~13 ~12 minecraft:cobblestone
setblock ~0 ~14 ~9 minecraft:cobblestone
setblock ~0 ~14 ~10 minecraft:cobblestone
setblock ~0 ~30 ~10 minecraft:spruce_planks
setblock ~0 ~30 ~11 minecraft:spruce_planks
setblock ~0 ~30 ~12 minecraft:spruce_planks
setblock ~0 ~30 ~13 minecraft:spruce_planks
setblock ~0 ~30 ~14 minecraft:spruce_planks
setblock ~0 ~31 ~7 minecraft:dark_oak_planks
setblock ~0 ~31 ~8 minecraft:dark_oak_planks
setblock ~0 ~31 ~9 minecraft:dark_oak_planks
setblock ~0 ~31 ~10 minecraft:dark_oak_planks
setblock ~0 ~31 ~11 minecraft:dark_oak_planks
setblock ~0 ~31 ~12 minecraft:dark_oak_planks
setblock ~0 ~31 ~13 minecraft:dark_oak_planks
setblock ~0 ~31 ~14 minecraft:dark_oak_planks
setblock ~0 ~31 ~15 minecraft:dark_oak_planks
setblock ~0 ~31 ~16 minecraft:dark_oak_planks
setblock ~0 ~32 ~9 minecraft:dark_oak_planks
setblock ~0 ~32 ~10 minecraft:dark_oak_planks
setblock ~0 ~32 ~11 minecraft:dark_oak_planks
setblock ~0 ~32 ~12 minecraft:dark_oak_planks
setblock ~0 ~32 ~13 minecraft:dark_oak_planks
setblock ~0 ~32 ~14 minecraft:dark_oak_planks
setblock ~0 ~32 ~15 minecraft:dark_oak_planks
setblock ~1 ~0 ~7 minecraft:mossy_cobblestone
setblock ~1 ~0 ~8 minecraft:mossy_cobblestone
setblock ~1 ~0 ~9 minecraft:mossy_cobblestone
setblock ~1 ~0 ~10 minecraft:mossy_cobblestone
setblock ~1 ~0 ~14 minecraft:mossy_cobblestone
setblock ~1 ~0 ~15 minecraft:mossy_cobblestone
setblock ~1 ~0 ~16 minecraft:mossy_cobblestone
setblock ~1 ~0 ~17 minecraft:mossy_cobblestone
setblock ~1 ~1 ~7 minecraft:mossy_cobblestone
setblock ~1 ~1 ~8 minecraft:cobblestone
setblock ~1 ~1 ~9 minecraft:mossy_cobblestone
setblock ~1 ~1 ~10 minecraft:cobblestone
setblock ~1 ~1 ~11 minecraft:oak_leaves[distance=7,persistent=true]
setblock ~1 ~1 ~12 minecraft:oak_leaves[distance=7,persistent=true]
setblock ~1 ~1 ~13 minecraft:mossy_cobblestone
setblock ~1 ~1 ~14 minecraft:mossy_cobblestone
setblock ~1 ~1 ~15 minecraft:oak_leaves[distance=7,persistent=true]
setblock ~1 ~1 ~16 minecraft:mossy_cobblestone
setblock ~1 ~1 ~17 minecraft:cobblestone
setblock ~1 ~2 ~8 minecraft:cracked_stone_bricks
setblock ~1 ~2 ~9 minecraft:polished_blackstone
setblock ~1 ~2 ~10 minecraft:mossy_cobblestone
setblock ~1 ~2 ~11 minecraft:mossy_cobblestone
setblock ~1 ~2 ~12 minecraft:cobblestone
setblock ~1 ~2 ~13 minecraft:cobblestone
setblock ~1 ~2 ~14 minecraft:cobblestone
setblock ~1 ~2 ~15 minecraft:oak_leaves[distance=7,persistent=true]
setblock ~1 ~2 ~16 minecraft:mossy_cobblestone
setblock ~1 ~3 ~8 minecraft:polished_blackstone
setblock ~1 ~3 ~9 minecraft:polished_blackstone
setblock ~1 ~3 ~10 minecraft:cobblestone
setblock ~1 ~3 ~11 minecraft:cobblestone
setblock ~1 ~3 ~12 minecraft:cobblestone
setblock ~1 ~3 ~13 minecraft:mossy_cobblestone
setblock ~1 ~3 ~14 minecraft:mossy_cobblestone
setblock ~1 ~3 ~15 minecraft:oak_leaves[distance=7,persistent=true]
setblock ~1 ~3 ~16 minecraft:oak_leaves[distance=7,persistent=true]
setblock ~1 ~4 ~9 minecraft:polished_blackstone
setblock ~1 ~4 ~10 minecraft:mossy_cobblestone
setblock ~1 ~4 ~11 minecraft:cobblestone
setblock ~1 ~4 ~12 minecraft:mossy_cobblestone
setblock ~1 ~4 ~13 minecraft:oak_leaves[distance=7,persistent=true]
setblock ~1 ~4 ~14 minecraft:oak_leaves[distance=7,persistent=true]
setblock ~1 ~4 ~15 minecraft:oak_leaves[distance=7,persistent=true]
setblock ~1 ~4 ~16 minecraft:oak_leaves[distance=7,persistent=true]
setblock ~1 ~5 ~9 minecraft:polished_blackstone
setblock ~1 ~5 ~10 minecraft:mossy_cobblestone
setblock ~1 ~5 ~11 minecraft:mossy_cobblestone
setblock ~1 ~5 ~12 minecraft:mossy_cobblestone
setblock ~1 ~5 ~13 minecraft:oak_leaves[distance=7,persistent=true]
setblock ~1 ~5 ~14 minecraft:oak_leaves[distance=7,persistent=true]
setblock ~1 ~5 ~15 minecraft:polished_blackstone
setblock ~1 ~5 ~16 minecraft:oak_leaves[distance=7,persistent=true]
setblock ~1 ~6 ~9 minecraft:polished_blackstone
setblock ~1 ~6 ~10 minecraft:stone_bricks
setblock ~1 ~6 ~11 minecraft:stone_bricks
setblock ~1 ~6 ~12 minecraft:cobblestone
setblock ~1 ~6 ~13 minecraft:cobblestone
setblock ~1 ~6 ~14 minecraft:mossy_cobblestone
setblock ~1 ~6 ~15 minecraft:oak_leaves[distance=7,persistent=true]
setblock ~1 ~7 ~9 minecraft:polished_blackstone
setblock ~1 ~7 ~10 minecraft:cobblestone
setblock ~1 ~7 ~11 minecraft:cobblestone
setblock ~1 ~7 ~12 minecraft:cobblestone
setblock ~1 ~7 ~13 minecraft:mossy_cobblestone
setblock ~1 ~7 ~14 minecraft:cobblestone
setblock ~1 ~7 ~15 minecraft:oak_leaves[distance=7,persistent=true]
setblock ~1 ~7 ~16 minecraft:oak_leaves[distance=7,persistent=true]
setblock ~1 ~8 ~9 minecraft:polished_blackstone
setblock ~1 ~8 ~10 minecraft:cobblestone
setblock ~1 ~8 ~11 minecraft:cobblestone
setblock ~1 ~8 ~12 minecraft:mossy_cobblestone
setblock ~1 ~8 ~13 minecraft:mossy_cobblestone
setblock ~1 ~8 ~14 minecraft:cobblestone
setblock ~1 ~8 ~15 minecraft:oak_leaves[distance=7,persistent=true]
setblock ~1 ~8 ~16 minecraft:oak_leaves[distance=7,persistent=true]
setblock ~1 ~9 ~9 minecraft:polished_blackstone
setblock ~1 ~9 ~10 minecraft:mossy_cobblestone
setblock ~1 ~9 ~11 minecraft:cobblestone
setblock ~1 ~9 ~12 minecraft:cobblestone
setblock ~1 ~9 ~13 minecraft:mossy_stone_bricks
setblock ~1 ~9 ~14 minecraft:oak_leaves[distance=7,persistent=true]
setblock ~1 ~9 ~15 minecraft:oak_leaves[distance=7,persistent=true]
setblock ~1 ~10 ~9 minecraft:polished_blackstone
setblock ~1 ~10 ~10 minecraft:cobblestone
setblock ~1 ~10 ~11 minecraft:cobblestone
setblock ~1 ~10 ~12 minecraft:cobblestone
setblock ~1 ~10 ~13 minecraft:cobblestone
setblock ~1 ~10 ~14 minecraft:oak_leaves[distance=7,persistent=true]
setblock ~1 ~10 ~15 minecraft:polished_blackstone
setblock ~1 ~11 ~9 minecraft:polished_blackstone
setblock ~1 ~11 ~10 minecraft:polished_blackstone
setblock ~1 ~11 ~11 minecraft:polished_blackstone
setblock ~1 ~11 ~12 minecraft:polished_blackstone
setblock ~1 ~11 ~13 minecraft:polished_blackstone
setblock ~1 ~11 ~14 minecraft:oak_leaves[distance=7,persistent=true]
setblock ~1 ~11 ~15 minecraft:mossy_stone_bricks
setblock ~1 ~12 ~8 minecraft:cobblestone
setblock ~1 ~12 ~9 minecraft:stone_bricks
setblock ~1 ~12 ~10 minecraft:cobblestone
setblock ~1 ~12 ~11 minecraft:cobblestone
setblock ~1 ~12 ~12 minecraft:polished_blackstone
setblock ~1 ~12 ~13 minecraft:oak_leaves[distance=7,persistent=true]
setblock ~1 ~12 ~14 minecraft:cobblestone
setblock ~1 ~12 ~15 minecraft:cobblestone
setblock ~1 ~12 ~16 minecraft:cobblestone
setblock ~1 ~13 ~8 minecraft:stone_bricks
setblock ~1 ~13 ~9 minecraft:cobblestone
setblock ~1 ~13 ~10 minecraft:oak_leaves[distance=7,persistent=true]
setblock ~1 ~13 ~11 minecraft:polished_blackstone
setblock ~1 ~13 ~12 minecraft:polished_blackstone
setblock ~1 ~13 ~13 minecraft:polished_blackstone
setblock ~1 ~13 ~14 minecraft:cobblestone
setblock ~1 ~13 ~15 minecraft:mossy_stone_bricks
setblock ~1 ~13 ~16 minecraft:cobblestone
setblock ~1 ~14 ~7 minecraft:cobblestone
setblock ~1 ~14 ~8 minecraft:cobblestone
setblock ~1 ~14 ~9 minecraft:cobblestone
setblock ~1 ~14 ~10 minecraft:mossy_stone_bricks
setblock ~1 ~14 ~11 minecraft:cobblestone
setblock ~1 ~14 ~12 minecraft:cobblestone
setblock ~1 ~14 ~13 minecraft:cracked_stone_bricks
setblock ~1 ~14 ~14 minecraft:polished_blackstone
setblock ~1 ~15 ~8 minecraft:cobblestone
setblock ~1 ~15 ~9 minecraft:oak_leaves[distance=7,persistent=true]
setblock ~1 ~15 ~10 minecraft:oak_leaves[distance=7,persistent=true]
setblock ~1 ~15 ~11 minecraft:cobblestone
setblock ~1 ~15 ~12 minecraft:cobblestone
setblock ~1 ~15 ~13 minecraft:mossy_stone_bricks
setblock ~1 ~16 ~8 minecraft:oak_leaves[distance=7,persistent=true]
setblock ~1 ~16 ~9 minecraft:oak_leaves[distance=7,persistent=true]
setblock ~1 ~16 ~11 minecraft:cobblestone
setblock ~1 ~16 ~12 minecraft:cobblestone
setblock ~1 ~16 ~13 minecraft:cobblestone
setblock ~1 ~17 ~12 minecraft:cobblestone
setblock ~1 ~17 ~13 minecraft:cobblestone
setblock ~1 ~18 ~11 minecraft:cobblestone
setblock ~1 ~20 ~12 minecraft:polished_blackstone
setblock ~1 ~21 ~9 minecraft:cobblestone
setblock ~1 ~21 ~10 minecraft:cobblestone
setblock ~1 ~21 ~11 minecraft:stone_bricks
setblock ~1 ~21 ~12 minecraft:cobblestone
setblock ~1 ~21 ~13 minecraft:cobblestone
setblock ~1 ~21 ~14 minecraft:cobblestone
setblock ~1 ~21 ~15 minecraft:stone_bricks
setblock ~1 ~22 ~9 minecraft:cobblestone
setblock ~1 ~22 ~10 minecraft:cobblestone
setblock ~1 ~22 ~11 minecraft:cobblestone
setblock ~1 ~22 ~12 minecraft:cobblestone
setblock ~1 ~22 ~13 minecraft:cobblestone
setblock ~1 ~22 ~14 minecraft:cobblestone
setblock ~1 ~22 ~15 minecraft:cobblestone
setblock ~1 ~23 ~9 minecraft:cobblestone
setblock ~1 ~23 ~10 minecraft:cobblestone
setblock ~1 ~23 ~11 minecraft:cobblestone
setblock ~1 ~23 ~12 minecraft:cracked_stone_bricks
setblock ~1 ~23 ~13 minecraft:cobblestone
setblock ~1 ~23 ~14 minecraft:cobblestone
setblock ~1 ~23 ~15 minecraft:cobblestone
setblock ~1 ~24 ~9 minecraft:cobblestone
setblock ~1 ~24 ~10 minecraft:cobblestone
setblock ~1 ~24 ~11 minecraft:cobblestone
setblock ~1 ~24 ~12 minecraft:cobblestone
setblock ~1 ~24 ~13 minecraft:cobblestone
setblock ~1 ~24 ~14 minecraft:cobblestone
setblock ~1 ~24 ~15 minecraft:cobblestone
setblock ~1 ~28 ~11 minecraft:cobblestone
setblock ~1 ~28 ~12 minecraft:mossy_stone_bricks
setblock ~1 ~29 ~11 minecraft:cobblestone
setblock ~1 ~29 ~12 minecraft:cobblestone
setblock ~1 ~30 ~7 minecraft:spruce_planks
setblock ~1 ~30 ~8 minecraft:spruce_planks
setblock ~1 ~30 ~9 minecraft:spruce_planks
setblock ~1 ~30 ~10 minecraft:cobblestone
setblock ~1 ~30 ~11 minecraft:cobblestone
setblock ~1 ~30 ~12 minecraft:cobblestone
setblock ~1 ~30 ~13 minecraft:spruce_planks
setblock ~1 ~30 ~14 minecraft:cobblestone
setblock ~1 ~30 ~15 minecraft:spruce_planks
setblock ~1 ~30 ~16 minecraft:spruce_planks
setblock ~1 ~30 ~17 minecraft:spruce_planks
setblock ~1 ~31 ~6 minecraft:dark_oak_planks
setblock ~1 ~31 ~7 minecraft:dark_oak_planks
setblock ~1 ~31 ~8 minecraft:dark_oak_planks
setblock ~1 ~31 ~9 minecraft:dark_oak_planks
setblock ~1 ~31 ~10 minecraft:dark_oak_planks
setblock ~1 ~31 ~11 minecraft:dark_oak_planks
setblock ~1 ~31 ~12 minecraft:dark_oak_planks
setblock ~1 ~31 ~13 minecraft:dark_oak_planks
setblock ~1 ~31 ~14 minecraft:dark_oak_planks
setblock ~1 ~31 ~15 minecraft:dark_oak_planks
setblock ~1 ~31 ~16 minecraft:dark_oak_planks
setblock ~1 ~31 ~17 minecraft:dark_oak_planks
setblock ~1 ~31 ~18 minecraft:dark_oak_planks
setblock ~1 ~32 ~7 minecraft:dark_oak_planks
setblock ~1 ~32 ~8 minecraft:dark_oak_planks
setblock ~1 ~32 ~9 minecraft:dark_oak_planks
setblock ~1 ~32 ~10 minecraft:dark_oak_planks
setblock ~1 ~32 ~11 minecraft:dark_oak_planks
setblock ~1 ~32 ~12 minecraft:dark_oak_planks
setblock ~1 ~32 ~13 minecraft:dark_oak_planks
setblock ~1 ~32 ~14 minecraft:dark_oak_planks
setblock ~1 ~32 ~15 minecraft:dark_oak_planks
setblock ~1 ~32 ~16 minecraft:dark_oak_planks
setblock ~1 ~32 ~17 minecraft:dark_oak_planks
setblock ~1 ~33 ~9 minecraft:dark_oak_planks
setblock ~1 ~33 ~10 minecraft:dark_oak_planks
setblock ~1 ~33 ~11 minecraft:dark_oak_planks
setblock ~1 ~33 ~12 minecraft:dark_oak_planks
setblock ~1 ~33 ~13 minecraft:dark_oak_planks
setblock ~1 ~33 ~14 minecraft:dark_oak_planks
setblock ~1 ~33 ~15 minecraft:dark_oak_planks
setblock ~2 ~0 ~5 minecraft:mossy_cobblestone
setblock ~2 ~0 ~6 minecraft:mossy_cobblestone
setblock ~2 ~0 ~7 minecraft:mossy_cobblestone
setblock ~2 ~0 ~17 minecraft:mossy_cobblestone
setblock ~2 ~0 ~18 minecraft:mossy_cobblestone
setblock ~2 ~1 ~6 minecraft:stone_bricks
setblock ~2 ~1 ~7 minecraft:mossy_cobblestone
setblock ~2 ~1 ~8 minecraft:mossy_cobblestone
setblock ~2 ~1 ~16 minecraft:cobblestone
setblock ~2 ~1 ~17 minecraft:mossy_cobblestone
setblock ~2 ~1 ~18 minecraft:cobblestone
setblock ~2 ~2 ~6 minecraft:cobblestone
setblock ~2 ~2 ~7 minecraft:mossy_cobblestone
setblock ~2 ~2 ~8 minecraft:mossy_cobblestone
setblock ~2 ~2 ~9 minecraft:mossy_cobblestone
setblock ~2 ~2 ~15 minecraft:mossy_cobblestone
setblock ~2 ~2 ~16 minecraft:mossy_cobblestone
setblock ~2 ~2 ~17 minecraft:mossy_cobblestone
setblock ~2 ~2 ~18 minecraft:mossy_cobblestone
setblock ~2 ~3 ~7 minecraft:mossy_cobblestone
setblock ~2 ~3 ~8 minecraft:mossy_cobblestone
setblock ~2 ~3 ~9 minecraft:mossy_cobblestone
setblock ~2 ~3 ~15 minecraft:mossy_cobblestone
setblock ~2 ~3 ~16 minecraft:mossy_cobblestone
setblock ~2 ~3 ~17 minecraft:cobblestone
setblock ~2 ~4 ~7 minecraft:cobblestone
setblock ~2 ~4 ~8 minecraft:stone_bricks
setblock ~2 ~4 ~9 minecraft:cobblestone
setblock ~2 ~4 ~10 minecraft:mossy_cobblestone
setblock ~2 ~4 ~14 minecraft:cobblestone
setblock ~2 ~4 ~15 minecraft:polished_blackstone
setblock ~2 ~4 ~16 minecraft:mossy_cobblestone
setblock ~2 ~4 ~17 minecraft:oak_leaves[distance=7,persistent=true]
setblock ~2 ~5 ~7 minecraft:mossy_cobblestone
setblock ~2 ~5 ~8 minecraft:mossy_cobblestone
setblock ~2 ~5 ~9 minecraft:mossy_cobblestone
setblock ~2 ~5 ~10 minecraft:cobblestone
setblock ~2 ~5 ~14 minecraft:cobblestone
setblock ~2 ~5 ~15 minecraft:cobblestone
setblock ~2 ~5 ~16 minecraft:mossy_cobblestone
setblock ~2 ~5 ~17 minecraft:oak_leaves[distance=7,persistent=true]
setblock ~2 ~5 ~18 minecraft:oak_leaves[distance=7,persistent=true]
setblock ~2 ~6 ~7 minecraft:mossy_cobblestone
setblock ~2 ~6 ~8 minecraft:stone_bricks
setblock ~2 ~6 ~9 minecraft:mossy_cobblestone
setblock ~2 ~6 ~10 minecraft:cobblestone
setblock ~2 ~6 ~14 minecraft:mossy_cobblestone
setblock ~2 ~6 ~15 minecraft:cobblestone
setblock ~2 ~6 ~16 minecraft:cobblestone
setblock ~2 ~6 ~17 minecraft:oak_leaves[distance=7,persistent=true]
setblock ~2 ~6 ~18 minecraft:oak_leaves[distance=7,persistent=true]
setblock ~2 ~7 ~7 minecraft:mossy_cobblestone
setblock ~2 ~7 ~8 minecraft:cobblestone
setblock ~2 ~7 ~9 minecraft:cobblestone
setblock ~2 ~7 ~10 minecraft:cobblestone
setblock ~2 ~7 ~14 minecraft:cobblestone
setblock ~2 ~7 ~15 minecraft:stone_bricks
setblock ~2 ~7 ~16 minecraft:cobblestone
setblock ~2 ~7 ~17 minecraft:oak_leaves[distance=7,persistent=true]
setblock ~2 ~8 ~7 minecraft:stone_bricks
setblock ~2 ~8 ~8 minecraft:cobblestone
setblock ~2 ~8 ~9 minecraft:polished_blackstone
setblock ~2 ~8 ~10 minecraft:stone_bricks
setblock ~2 ~8 ~11 minecraft:cobblestone
setblock ~2 ~8 ~13 minecraft:cobblestone
setblock ~2 ~8 ~14 minecraft:cobblestone
setblock ~2 ~8 ~15 minecraft:cobblestone
setblock ~2 ~8 ~16 minecraft:oak_leaves[distance=7,persistent=true]
setblock ~2 ~8 ~17 minecraft:oak_leaves[distance=7,persistent=true]
setblock ~2 ~8 ~18 minecraft:oak_leaves[distance=7,persistent=true]
setblock ~2 ~9 ~7 minecraft:cobblestone
setblock ~2 ~9 ~8 minecraft:mossy_cobblestone
setblock ~2 ~9 ~9 minecraft:polished_blackstone
setblock ~2 ~9 ~10 minecraft:cobblestone
setblock ~2 ~9 ~11 minecraft:cracked_stone_bricks
setblock ~2 ~9 ~12 minecraft:cobblestone
setblock ~2 ~9 ~13 minecraft:mossy_cobblestone
setblock ~2 ~9 ~14 minecraft:cobblestone
setblock ~2 ~9 ~15 minecraft:cracked_stone_bricks
setblock ~2 ~9 ~16 minecraft:mossy_stone_bricks
setblock ~2 ~10 ~7 minecraft:oak_leaves[distance=7,persistent=true]
setblock ~2 ~10 ~8 minecraft:cobblestone
setblock ~2 ~10 ~9 minecraft:mossy_cobblestone
setblock ~2 ~10 ~10 minecraft:cracked_stone_bricks
setblock ~2 ~10 ~11 minecraft:mossy_cobblestone
setblock ~2 ~10 ~12 minecraft:cobblestone
setblock ~2 ~10 ~13 minecraft:cobblestone
setblock ~2 ~10 ~14 minecraft:stone_bricks
setblock ~2 ~10 ~15 minecraft:cobblestone
setblock ~2 ~10 ~16 minecraft:stone_bricks
setblock ~2 ~11 ~7 minecraft:polished_blackstone
setblock ~2 ~11 ~8 minecraft:oak_leaves[distance=7,persistent=true]
setblock ~2 ~11 ~9 minecraft:polished_blackstone
setblock ~2 ~11 ~10 minecraft:polished_blackstone
setblock ~2 ~11 ~11 minecraft:polished_blackstone
setblock ~2 ~11 ~12 minecraft:polished_blackstone
setblock ~2 ~11 ~13 minecraft:polished_blackstone
setblock ~2 ~11 ~14 minecraft:polished_blackstone
setblock ~2 ~11 ~15 minecraft:polished_blackstone
setblock ~2 ~11 ~16 minecraft:polished_blackstone
setblock ~2 ~11 ~17 minecraft:cobblestone
setblock ~2 ~12 ~6 minecraft:cobblestone
setblock ~2 ~12 ~7 minecraft:cobblestone
setblock ~2 ~12 ~8 minecraft:oak_leaves[distance=7,persistent=true]
setblock ~2 ~12 ~9 minecraft:cobblestone
setblock ~2 ~12 ~10 minecraft:cracked_stone_bricks
setblock ~2 ~12 ~11 minecraft:cobblestone
setblock ~2 ~12 ~12 minecraft:cobblestone
setblock ~2 ~12 ~13 minecraft:cobblestone
setblock ~2 ~12 ~14 minecraft:cobblestone
setblock ~2 ~12 ~15 minecraft:cracked_stone_bricks
setblock ~2 ~12 ~16 minecraft:cobblestone
setblock ~2 ~12 ~17 minecraft:cobblestone
setblock ~2 ~12 ~18 minecraft:cobblestone
setblock ~2 ~13 ~6 minecraft:cobblestone
setblock ~2 ~13 ~7 minecraft:cobblestone
setblock ~2 ~13 ~8 minecraft:polished_blackstone
setblock ~2 ~13 ~9 minecraft:cobblestone
setblock ~2 ~13 ~10 minecraft:polished_blackstone
setblock ~2 ~13 ~11 minecraft:polished_blackstone
setblock ~2 ~13 ~12 minecraft:polished_blackstone
setblock ~2 ~13 ~13 minecraft:polished_blackstone
setblock ~2 ~13 ~14 minecraft:polished_blackstone
setblock ~2 ~13 ~15 minecraft:cobblestone
setblock ~2 ~13 ~16 minecraft:polished_blackstone
setblock ~2 ~13 ~17 minecraft:cobblestone
setblock ~2 ~14 ~6 minecraft:cobblestone
setblock ~2 ~14 ~7 minecraft:cobblestone
setblock ~2 ~14 ~8 minecraft:cracked_stone_bricks
setblock ~2 ~14 ~9 minecraft:cobblestone
setblock ~2 ~14 ~10 minecraft:cobblestone
setblock ~2 ~14 ~11 minecraft:cobblestone
setblock ~2 ~14 ~12 minecraft:cobblestone
setblock ~2 ~14 ~13 minecraft:cobblestone
setblock ~2 ~14 ~14 minecraft:cobblestone
setblock ~2 ~14 ~15 minecraft:cobblestone
setblock ~2 ~14 ~16 minecraft:cracked_stone_bricks
setblock ~2 ~15 ~7 minecraft:cobblestone
setblock ~2 ~15 ~8 minecraft:mossy_stone_bricks
setblock ~2 ~15 ~9 minecraft:oak_leaves[distance=7,persistent=true]
setblock ~2 ~15 ~10 minecraft:cobblestone
setblock ~2 ~15 ~11 minecraft:cobblestone
setblock ~2 ~15 ~12 minecraft:stone_bricks
setblock ~2 ~15 ~13 minecraft:stone_bricks
setblock ~2 ~15 ~14 minecraft:cobblestone
setblock ~2 ~15 ~15 minecraft:stone_bricks
setblock ~2 ~15 ~16 minecraft:cobblestone
setblock ~2 ~16 ~8 minecraft:oak_leaves[distance=7,persistent=true]
setblock ~2 ~16 ~9 minecraft:oak_leaves[distance=7,persistent=true]
setblock ~2 ~16 ~10 minecraft:cobblestone
setblock ~2 ~16 ~11 minecraft:cobblestone
setblock ~2 ~16 ~12 minecraft:cobblestone
setblock ~2 ~16 ~13 minecraft:cobblestone
setblock ~2 ~16 ~14 minecraft:cracked_stone_bricks
setblock ~2 ~16 ~15 minecraft:cobblestone
setblock ~2 ~16 ~16 minecraft:cobblestone
setblock ~2 ~17 ~9 minecraft:cobblestone
setblock ~2 ~17 ~10 minecraft:cobblestone
setblock ~2 ~17 ~11 minecraft:cobblestone
setblock ~2 ~17 ~12 minecraft:cracked_stone_bricks
setblock ~2 ~17 ~13 minecraft:cobblestone
setblock ~2 ~17 ~14 minecraft:cobblestone
setblock ~2 ~17 ~15 minecraft:cobblestone
setblock ~2 ~17 ~16 minecraft:cobblestone
setblock ~2 ~18 ~9 minecraft:cobblestone
setblock ~2 ~18 ~10 minecraft:cobblestone
setblock ~2 ~18 ~11 minecraft:cobblestone
setblock ~2 ~18 ~12 minecraft:cobblestone
setblock ~2 ~18 ~13 minecraft:cobblestone
setblock ~2 ~18 ~14 minecraft:cobblestone
setblock ~2 ~18 ~15 minecraft:cobblestone
setblock ~2 ~19 ~7 minecraft:cobblestone
setblock ~2 ~19 ~8 minecraft:cobblestone
setblock ~2 ~19 ~9 minecraft:cobblestone
setblock ~2 ~19 ~10 minecraft:cobblestone
setblock ~2 ~19 ~11 minecraft:cobblestone
setblock ~2 ~19 ~12 minecraft:cobblestone
setblock ~2 ~19 ~13 minecraft:cobblestone
setblock ~2 ~19 ~14 minecraft:cobblestone
setblock ~2 ~19 ~15 minecraft:cobblestone
setblock ~2 ~20 ~7 minecraft:cobblestone
setblock ~2 ~20 ~8 minecraft:stone_bricks
setblock ~2 ~20 ~9 minecraft:polished_blackstone
setblock ~2 ~20 ~10 minecraft:cobblestone
setblock ~2 ~20 ~11 minecraft:cobblestone
setblock ~2 ~20 ~12 minecraft:cobblestone
setblock ~2 ~20 ~13 minecraft:stone_bricks
setblock ~2 ~20 ~14 minecraft:cobblestone
setblock ~2 ~20 ~15 minecraft:cobblestone
setblock ~2 ~20 ~16 minecraft:polished_blackstone
setblock ~2 ~21 ~7 minecraft:cobblestone
setblock ~2 ~21 ~8 minecraft:cobblestone
setblock ~2 ~21 ~9 minecraft:polished_blackstone
setblock ~2 ~21 ~10 minecraft:polished_blackstone
setblock ~2 ~21 ~11 minecraft:polished_blackstone
setblock ~2 ~21 ~12 minecraft:polished_blackstone
setblock ~2 ~21 ~13 minecraft:polished_blackstone
setblock ~2 ~21 ~14 minecraft:polished_blackstone
setblock ~2 ~21 ~15 minecraft:polished_blackstone
setblock ~2 ~21 ~16 minecraft:cobblestone
setblock ~2 ~21 ~17 minecraft:cobblestone
setblock ~2 ~22 ~7 minecraft:cobblestone
setblock ~2 ~22 ~8 minecraft:cobblestone
setblock ~2 ~22 ~9 minecraft:stone_bricks
setblock ~2 ~22 ~10 minecraft:cobblestone
setblock ~2 ~22 ~11 minecraft:stone_bricks
setblock ~2 ~22 ~12 minecraft:cracked_stone_bricks
setblock ~2 ~22 ~13 minecraft:cobblestone
setblock ~2 ~22 ~14 minecraft:cobblestone
setblock ~2 ~22 ~15 minecraft:cobblestone
setblock ~2 ~22 ~16 minecraft:mossy_stone_bricks
setblock ~2 ~22 ~17 minecraft:stone_bricks
setblock ~2 ~23 ~9 minecraft:cobblestone
setblock ~2 ~23 ~10 minecraft:cobblestone
setblock ~2 ~23 ~11 minecraft:cobblestone
setblock ~2 ~23 ~12 minecraft:cobblestone
setblock ~2 ~23 ~13 minecraft:cobblestone
setblock ~2 ~23 ~14 minecraft:cobblestone
setblock ~2 ~23 ~15 minecraft:stone_bricks
setblock ~2 ~24 ~9 minecraft:mossy_stone_bricks
setblock ~2 ~24 ~10 minecraft:cobblestone
setblock ~2 ~24 ~11 minecraft:cobblestone
setblock ~2 ~24 ~12 minecraft:cobblestone
setblock ~2 ~24 ~13 minecraft:cobblestone
setblock ~2 ~24 ~14 minecraft:cobblestone
setblock ~2 ~24 ~15 minecraft:mossy_stone_bricks
setblock ~2 ~25 ~9 minecraft:cobblestone
setblock ~2 ~25 ~10 minecraft:cobblestone
setblock ~2 ~25 ~14 minecraft:cobblestone
setblock ~2 ~25 ~15 minecraft:stone_bricks
setblock ~2 ~26 ~9 minecraft:cobblestone
setblock ~2 ~26 ~10 minecraft:cobblestone
setblock ~2 ~26 ~14 minecraft:cobblestone
setblock ~2 ~26 ~15 minecraft:cracked_stone_bricks
setblock ~2 ~27 ~9 minecraft:cobblestone
setblock ~2 ~27 ~10 minecraft:stone_bricks
setblock ~2 ~27 ~14 minecraft:cracked_stone_bricks
setblock ~2 ~27 ~15 minecraft:stone_bricks
setblock ~2 ~28 ~9 minecraft:mossy_stone_bricks
setblock ~2 ~28 ~10 minecraft:cobblestone
setblock ~2 ~28 ~11 minecraft:cobblestone
setblock ~2 ~28 ~12 minecraft:cobblestone
setblock ~2 ~28 ~14 minecraft:cobblestone
setblock ~2 ~29 ~9 minecraft:polished_blackstone
setblock ~2 ~29 ~10 minecraft:polished_blackstone
setblock ~2 ~29 ~11 minecraft:polished_blackstone
setblock ~2 ~29 ~12 minecraft:cobblestone
setblock ~2 ~29 ~13 minecraft:polished_blackstone
setblock ~2 ~29 ~14 minecraft:polished_blackstone
setblock ~2 ~29 ~15 minecraft:polished_blackstone
setblock ~2 ~30 ~6 minecraft:spruce_planks
setblock ~2 ~30 ~7 minecraft:spruce_planks
setblock ~2 ~30 ~8 minecraft:stone_bricks
setblock ~2 ~30 ~9 minecraft:cobblestone
setblock ~2 ~30 ~10 minecraft:cobblestone
setblock ~2 ~30 ~11 minecraft:cobblestone
setblock ~2 ~30 ~12 minecraft:cobblestone
setblock ~2 ~30 ~13 minecraft:cobblestone
setblock ~2 ~30 ~14 minecraft:cobblestone
setblock ~2 ~30 ~15 minecraft:cobblestone
setblock ~2 ~30 ~16 minecraft:cobblestone
setblock ~2 ~30 ~17 minecraft:spruce_planks
setblock ~2 ~30 ~18 minecraft:spruce_planks
setblock ~2 ~31 ~4 minecraft:dark_oak_planks
setblock ~2 ~31 ~5 minecraft:dark_oak_planks
setblock ~2 ~31 ~6 minecraft:dark_oak_planks
setblock ~2 ~31 ~7 minecraft:dark_oak_planks
setblock ~2 ~31 ~8 minecraft:dark_oak_planks
setblock ~2 ~31 ~9 minecraft:dark_oak_planks
setblock ~2 ~31 ~10 minecraft:dark_oak_planks
setblock ~2 ~31 ~11 minecraft:dark_oak_planks
setblock ~2 ~31 ~12 minecraft:dark_oak_planks
setblock ~2 ~31 ~13 minecraft:dark_oak_planks
setblock ~2 ~31 ~14 minecraft:dark_oak_planks
setblock ~2 ~31 ~15 minecraft:dark_oak_planks
setblock ~2 ~31 ~16 minecraft:dark_oak_planks
setblock ~2 ~31 ~17 minecraft:dark_oak_planks
setblock ~2 ~31 ~18 minecraft:dark_oak_planks
setblock ~2 ~31 ~19 minecraft:dark_oak_planks
setblock ~2 ~32 ~5 minecraft:dark_oak_planks
setblock ~2 ~32 ~6 minecraft:dark_oak_planks
setblock ~2 ~32 ~7 minecraft:dark_oak_planks
setblock ~2 ~32 ~8 minecraft:dark_oak_planks
setblock ~2 ~32 ~9 minecraft:dark_oak_planks
setblock ~2 ~32 ~15 minecraft:dark_oak_planks
setblock ~2 ~32 ~16 minecraft:dark_oak_planks
setblock ~2 ~32 ~17 minecraft:dark_oak_planks
setblock ~2 ~32 ~18 minecraft:dark_oak_planks
setblock ~2 ~33 ~7 minecraft:dark_oak_planks
setblock ~2 ~33 ~8 minecraft:dark_oak_planks
setblock ~2 ~33 ~9 minecraft:dark_oak_planks
setblock ~2 ~33 ~10 minecraft:dark_oak_planks
setblock ~2 ~33 ~11 minecraft:dark_oak_planks
setblock ~2 ~33 ~12 minecraft:dark_oak_planks
setblock ~2 ~33 ~13 minecraft:dark_oak_planks
setblock ~2 ~33 ~14 minecraft:dark_oak_planks
setblock ~2 ~33 ~15 minecraft:dark_oak_planks
setblock ~2 ~33 ~16 minecraft:dark_oak_planks
setblock ~2 ~33 ~17 minecraft:dark_oak_planks
setblock ~2 ~34 ~8 minecraft:dark_oak_planks
setblock ~2 ~34 ~9 minecraft:dark_oak_planks
setblock ~2 ~34 ~10 minecraft:dark_oak_planks
setblock ~2 ~34 ~11 minecraft:dark_oak_planks
setblock ~2 ~34 ~12 minecraft:dark_oak_planks
setblock ~2 ~34 ~13 minecraft:dark_oak_planks
setblock ~2 ~34 ~14 minecraft:dark_oak_planks
setblock ~2 ~34 ~15 minecraft:dark_oak_planks
setblock ~3 ~0 ~4 minecraft:oak_leaves[distance=7,persistent=true]
setblock ~3 ~0 ~5 minecraft:cobblestone
setblock ~3 ~0 ~6 minecraft:cobblestone
setblock ~3 ~0 ~18 minecraft:mossy_cobblestone
setblock ~3 ~0 ~19 minecraft:mossy_cobblestone
setblock ~3 ~1 ~5 minecraft:cobblestone
setblock ~3 ~1 ~6 minecraft:cracked_stone_bricks
setblock ~3 ~1 ~18 minecraft:cobblestone
setblock ~3 ~1 ~19 minecraft:mossy_cobblestone
setblock ~3 ~2 ~5 minecraft:oak_leaves[distance=7,persistent=true]
setblock ~3 ~2 ~6 minecraft:mossy_cobblestone
setblock ~3 ~2 ~7 minecraft:mossy_cobblestone
setblock ~3 ~2 ~17 minecraft:mossy_cobblestone
setblock ~3 ~2 ~18 minecraft:polished_blackstone
setblock ~3 ~2 ~19 minecraft:mossy_cobblestone
setblock ~3 ~3 ~5 minecraft:oak_leaves[distance=7,persistent=true]
setblock ~3 ~3 ~6 minecraft:mossy_cobblestone
setblock ~3 ~3 ~7 minecraft:cobblestone
setblock ~3 ~3 ~17 minecraft:mossy_cobblestone
setblock ~3 ~3 ~18 minecraft:polished_blackstone
setblock ~3 ~4 ~5 minecraft:polished_blackstone
setblock ~3 ~4 ~6 minecraft:polished_blackstone
setblock ~3 ~4 ~7 minecraft:mossy_cobblestone
setblock ~3 ~4 ~17 minecraft:cobblestone
setblock ~3 ~4 ~18 minecraft:polished_blackstone
setblock ~3 ~5 ~5 minecraft:oak_leaves[distance=7,persistent=true]
setblock ~3 ~5 ~6 minecraft:polished_blackstone
setblock ~3 ~5 ~7 minecraft:cobblestone
setblock ~3 ~5 ~17 minecraft:mossy_cobblestone
setblock ~3 ~5 ~18 minecraft:polished_blackstone
setblock ~3 ~6 ~5 minecraft:oak_leaves[distance=7,persistent=true]
setblock ~3 ~6 ~6 minecraft:polished_blackstone
setblock ~3 ~6 ~7 minecraft:mossy_stone_bricks
setblock ~3 ~6 ~17 minecraft:cobblestone
setblock ~3 ~6 ~18 minecraft:polished_blackstone
setblock ~3 ~7 ~5 minecraft:oak_leaves[distance=7,persistent=true]
setblock ~3 ~7 ~6 minecraft:polished_blackstone
setblock ~3 ~7 ~7 minecraft:cracked_stone_bricks
setblock ~3 ~7 ~16 minecraft:cobblestone
setblock ~3 ~7 ~17 minecraft:cobblestone
setblock ~3 ~7 ~18 minecraft:oak_leaves[distance=7,persistent=true]
setblock ~3 ~8 ~5 minecraft:oak_leaves[distance=7,persistent=true]
setblock ~3 ~8 ~6 minecraft:polished_blackstone
setblock ~3 ~8 ~7 minecraft:stone_bricks
setblock ~3 ~8 ~16 minecraft:cobblestone
setblock ~3 ~8 ~17 minecraft:mossy_cobblestone
setblock ~3 ~8 ~18 minecraft:oak_leaves[distance=7,persistent=true]
setblock ~3 ~9 ~6 minecraft:oak_leaves[distance=7,persistent=true]
setblock ~3 ~9 ~7 minecraft:mossy_cobblestone
setblock ~3 ~9 ~8 minecraft:mossy_cobblestone
setblock ~3 ~9 ~16 minecraft:mossy_cobblestone
setblock ~3 ~9 ~17 minecraft:stone_bricks
setblock ~3 ~9 ~18 minecraft:polished_blackstone
setblock ~3 ~10 ~6 minecraft:polished_blackstone
setblock ~3 ~10 ~7 minecraft:stone_bricks
setblock ~3 ~10 ~8 minecraft:mossy_cobblestone
setblock ~3 ~10 ~16 minecraft:mossy_cobblestone
setblock ~3 ~10 ~17 minecraft:cobblestone
setblock ~3 ~10 ~18 minecraft:polished_blackstone
setblock ~3 ~11 ~6 minecraft:polished_blackstone
setblock ~3 ~11 ~7 minecraft:polished_blackstone
setblock ~3 ~11 ~8 minecraft:polished_blackstone
setblock ~3 ~11 ~16 minecraft:polished_blackstone
setblock ~3 ~11 ~17 minecraft:cobblestone
setblock ~3 ~11 ~18 minecraft:polished_blackstone
setblock ~3 ~12 ~5 minecraft:cobblestone
setblock ~3 ~12 ~6 minecraft:polished_blackstone
setblock ~3 ~12 ~7 minecraft:cobblestone
setblock ~3 ~12 ~8 minecraft:cobblestone
setblock ~3 ~12 ~16 minecraft:cobblestone
setblock ~3 ~12 ~17 minecraft:cobblestone
setblock ~3 ~12 ~18 minecraft:cobblestone
setblock ~3 ~12 ~19 minecraft:stone_bricks
setblock ~3 ~13 ~5 minecraft:stone_bricks
setblock ~3 ~13 ~6 minecraft:polished_blackstone
setblock ~3 ~13 ~7 minecraft:cobblestone
setblock ~3 ~13 ~8 minecraft:polished_blackstone
setblock ~3 ~13 ~16 minecraft:polished_blackstone
setblock ~3 ~13 ~17 minecraft:polished_blackstone
setblock ~3 ~13 ~18 minecraft:cobblestone
setblock ~3 ~13 ~19 minecraft:cobblestone
setblock ~3 ~14 ~4 minecraft:cobblestone
setblock ~3 ~14 ~5 minecraft:cobblestone
setblock ~3 ~14 ~6 minecraft:cobblestone
setblock ~3 ~14 ~7 minecraft:cobblestone
setblock ~3 ~14 ~8 minecraft:cobblestone
setblock ~3 ~14 ~9 minecraft:cobblestone
setblock ~3 ~14 ~16 minecraft:cobblestone
setblock ~3 ~14 ~17 minecraft:cobblestone
setblock ~3 ~15 ~5 minecraft:cobblestone
setblock ~3 ~15 ~6 minecraft:cobblestone
setblock ~3 ~15 ~7 minecraft:cobblestone
setblock ~3 ~15 ~8 minecraft:cobblestone
setblock ~3 ~15 ~16 minecraft:mossy_stone_bricks
setblock ~3 ~15 ~17 minecraft:cobblestone
setblock ~3 ~16 ~16 minecraft:cobblestone
setblock ~3 ~16 ~17 minecraft:cobblestone
setblock ~3 ~17 ~15 minecraft:mossy_stone_bricks
setblock ~3 ~17 ~16 minecraft:cobblestone
setblock ~3 ~17 ~17 minecraft:cobblestone
setblock ~3 ~18 ~9 minecraft:cobblestone
setblock ~3 ~18 ~15 minecraft:cracked_stone_bricks
setblock ~3 ~18 ~16 minecraft:cobblestone
setblock ~3 ~18 ~17 minecraft:cobblestone
setblock ~3 ~19 ~7 minecraft:cobblestone
setblock ~3 ~19 ~8 minecraft:cobblestone
setblock ~3 ~19 ~9 minecraft:cobblestone
setblock ~3 ~19 ~10 minecraft:cobblestone
setblock ~3 ~19 ~15 minecraft:stone_bricks
setblock ~3 ~19 ~16 minecraft:cobblestone
setblock ~3 ~19 ~17 minecraft:cobblestone
setblock ~3 ~20 ~7 minecraft:cobblestone
setblock ~3 ~20 ~8 minecraft:cobblestone
setblock ~3 ~20 ~9 minecraft:cobblestone
setblock ~3 ~20 ~15 minecraft:polished_blackstone
setblock ~3 ~20 ~16 minecraft:cobblestone
setblock ~3 ~20 ~17 minecraft:polished_blackstone
setblock ~3 ~21 ~6 minecraft:stone_bricks
setblock ~3 ~21 ~7 minecraft:polished_blackstone
setblock ~3 ~21 ~8 minecraft:polished_blackstone
setblock ~3 ~21 ~9 minecraft:polished_blackstone
setblock ~3 ~21 ~15 minecraft:polished_blackstone
setblock ~3 ~21 ~16 minecraft:polished_blackstone
setblock ~3 ~21 ~17 minecraft:cobblestone
setblock ~3 ~21 ~18 minecraft:cobblestone
setblock ~3 ~22 ~6 minecraft:stone_bricks
setblock ~3 ~22 ~7 minecraft:cobblestone
setblock ~3 ~22 ~8 minecraft:stone_bricks
setblock ~3 ~22 ~9 minecraft:cobblestone
setblock ~3 ~22 ~15 minecraft:stone_bricks
setblock ~3 ~22 ~16 minecraft:cobblestone
setblock ~3 ~22 ~17 minecraft:cobblestone
setblock ~3 ~22 ~18 minecraft:cobblestone
setblock ~3 ~23 ~7 minecraft:cobblestone
setblock ~3 ~23 ~8 minecraft:cobblestone
setblock ~3 ~23 ~9 minecraft:cobblestone
setblock ~3 ~23 ~10 minecraft:cobblestone
setblock ~3 ~23 ~11 minecraft:cobblestone
setblock ~3 ~23 ~12 minecraft:cobblestone
setblock ~3 ~23 ~13 minecraft:cobblestone
setblock ~3 ~23 ~14 minecraft:cracked_stone_bricks
setblock ~3 ~23 ~15 minecraft:cobblestone
setblock ~3 ~23 ~16 minecraft:cobblestone
setblock ~3 ~23 ~17 minecraft:cobblestone
setblock ~3 ~24 ~7 minecraft:cobblestone
setblock ~3 ~24 ~8 minecraft:cobblestone
setblock ~3 ~24 ~9 minecraft:cobblestone
setblock ~3 ~24 ~10 minecraft:cobblestone
setblock ~3 ~24 ~12 minecraft:polished_blackstone
setblock ~3 ~24 ~13 minecraft:cobblestone
setblock ~3 ~24 ~14 minecraft:cobblestone
setblock ~3 ~24 ~15 minecraft:cobblestone
setblock ~3 ~24 ~16 minecraft:cobblestone
setblock ~3 ~24 ~17 minecraft:cobblestone
setblock ~3 ~25 ~7 minecraft:stone_bricks
setblock ~3 ~25 ~8 minecraft:cobblestone
setblock ~3 ~25 ~9 minecraft:cobblestone
setblock ~3 ~25 ~10 minecraft:cobblestone
setblock ~3 ~25 ~12 minecraft:polished_blackstone
setblock ~3 ~25 ~13 minecraft:cobblestone
setblock ~3 ~25 ~14 minecraft:cracked_stone_bricks
setblock ~3 ~25 ~15 minecraft:cobblestone
setblock ~3 ~25 ~16 minecraft:cobblestone
setblock ~3 ~25 ~17 minecraft:cobblestone
setblock ~3 ~26 ~7 minecraft:cobblestone
setblock ~3 ~26 ~8 minecraft:cobblestone
setblock ~3 ~26 ~9 minecraft:cobblestone
setblock ~3 ~26 ~10 minecraft:cobblestone
setblock ~3 ~26 ~11 minecraft:polished_blackstone
setblock ~3 ~26 ~12 minecraft:polished_blackstone
setblock ~3 ~26 ~13 minecraft:stone_bricks
setblock ~3 ~26 ~14 minecraft:cracked_stone_bricks
setblock ~3 ~26 ~15 minecraft:cobblestone
setblock ~3 ~26 ~16 minecraft:cobblestone
setblock ~3 ~27 ~7 minecraft:cobblestone
setblock ~3 ~27 ~8 minecraft:stone_bricks
setblock ~3 ~27 ~9 minecraft:cobblestone
setblock ~3 ~27 ~10 minecraft:cobblestone
setblock ~3 ~27 ~11 minecraft:stone_bricks
setblock ~3 ~27 ~12 minecraft:polished_blackstone
setblock ~3 ~27 ~13 minecraft:cobblestone
setblock ~3 ~27 ~14 minecraft:stone_bricks
setblock ~3 ~27 ~15 minecraft:cobblestone
setblock ~3 ~27 ~16 minecraft:cobblestone
setblock ~3 ~28 ~7 minecraft:cobblestone
setblock ~3 ~28 ~8 minecraft:cobblestone
setblock ~3 ~28 ~9 minecraft:cobblestone
setblock ~3 ~28 ~10 minecraft:cobblestone
setblock ~3 ~28 ~11 minecraft:cobblestone
setblock ~3 ~28 ~13 minecraft:cobblestone
setblock ~3 ~28 ~14 minecraft:cobblestone
setblock ~3 ~28 ~15 minecraft:cobblestone
setblock ~3 ~28 ~16 minecraft:cobblestone
setblock ~3 ~29 ~7 minecraft:polished_blackstone
setblock ~3 ~29 ~8 minecraft:polished_blackstone
setblock ~3 ~29 ~9 minecraft:polished_blackstone
setblock ~3 ~29 ~10 minecraft:polished_blackstone
setblock ~3 ~29 ~11 minecraft:polished_blackstone
setblock ~3 ~29 ~12 minecraft:cobblestone
setblock ~3 ~29 ~13 minecraft:cobblestone
setblock ~3 ~29 ~14 minecraft:polished_blackstone
setblock ~3 ~29 ~15 minecraft:polished_blackstone
setblock ~3 ~29 ~16 minecraft:polished_blackstone
setblock ~3 ~29 ~17 minecraft:polished_blackstone
setblock ~3 ~30 ~5 minecraft:spruce_planks
setblock ~3 ~30 ~6 minecraft:cobblestone
setblock ~3 ~30 ~7 minecraft:cobblestone
setblock ~3 ~30 ~8 minecraft:cobblestone
setblock ~3 ~30 ~9 minecraft:stone_bricks
setblock ~3 ~30 ~10 minecraft:cobblestone
setblock ~3 ~30 ~11 minecraft:cobblestone
setblock ~3 ~30 ~12 minecraft:cobblestone
setblock ~3 ~30 ~13 minecraft:spruce_planks
setblock ~3 ~30 ~14 minecraft:cobblestone
setblock ~3 ~30 ~15 minecraft:cobblestone
setblock ~3 ~30 ~16 minecraft:cobblestone
setblock ~3 ~30 ~17 minecraft:cobblestone
setblock ~3 ~30 ~18 minecraft:spruce_planks
setblock ~3 ~30 ~19 minecraft:spruce_planks
setblock ~3 ~31 ~4 minecraft:dark_oak_planks
setblock ~3 ~31 ~5 minecraft:dark_oak_planks
setblock ~3 ~31 ~6 minecraft:dark_oak_planks
setblock ~3 ~31 ~7 minecraft:dark_oak_planks
setblock ~3 ~31 ~8 minecraft:dark_oak_planks
setblock ~3 ~31 ~9 minecraft:dark_oak_planks
setblock ~3 ~31 ~10 minecraft:dark_oak_planks
setblock ~3 ~31 ~11 minecraft:dark_oak_planks
setblock ~3 ~31 ~12 minecraft:dark_oak_planks
setblock ~3 ~31 ~13 minecraft:dark_oak_planks
setblock ~3 ~31 ~14 minecraft:dark_oak_planks
setblock ~3 ~31 ~15 minecraft:dark_oak_planks
setblock ~3 ~31 ~16 minecraft:dark_oak_planks
setblock ~3 ~31 ~17 minecraft:dark_oak_planks
setblock ~3 ~31 ~18 minecraft:dark_oak_planks
setblock ~3 ~31 ~19 minecraft:dark_oak_planks
setblock ~3 ~31 ~20 minecraft:dark_oak_planks
setblock ~3 ~32 ~4 minecraft:dark_oak_planks
setblock ~3 ~32 ~5 minecraft:dark_oak_planks
setblock ~3 ~32 ~6 minecraft:dark_oak_planks
setblock ~3 ~32 ~7 minecraft:dark_oak_planks
setblock ~3 ~32 ~17 minecraft:dark_oak_planks
setblock ~3 ~32 ~18 minecraft:dark_oak_planks
setblock ~3 ~32 ~19 minecraft:dark_oak_planks
setblock ~3 ~33 ~6 minecraft:dark_oak_planks
setblock ~3 ~33 ~7 minecraft:dark_oak_planks
setblock ~3 ~33 ~8 minecraft:dark_oak_planks
setblock ~3 ~33 ~9 minecraft:dark_oak_planks
setblock ~3 ~33 ~15 minecraft:dark_oak_planks
setblock ~3 ~33 ~16 minecraft:dark_oak_planks
setblock ~3 ~33 ~17 minecraft:dark_oak_planks
setblock ~3 ~33 ~18 minecraft:dark_oak_planks
setblock ~3 ~34 ~7 minecraft:dark_oak_planks
setblock ~3 ~34 ~8 minecraft:dark_oak_planks
setblock ~3 ~34 ~9 minecraft:dark_oak_planks
setblock ~3 ~34 ~10 minecraft:dark_oak_planks
setblock ~3 ~34 ~11 minecraft:dark_oak_planks
setblock ~3 ~34 ~12 minecraft:dark_oak_planks
setblock ~3 ~34 ~13 minecraft:dark_oak_planks
setblock ~3 ~34 ~14 minecraft:dark_oak_planks
setblock ~3 ~34 ~15 minecraft:dark_oak_planks
setblock ~3 ~34 ~16 minecraft:dark_oak_planks
setblock ~3 ~34 ~17 minecraft:dark_oak_planks
setblock ~3 ~35 ~8 minecraft:dark_oak_planks
setblock ~3 ~35 ~9 minecraft:dark_oak_planks
setblock ~3 ~35 ~10 minecraft:dark_oak_planks
setblock ~3 ~35 ~11 minecraft:dark_oak_planks
setblock ~3 ~35 ~12 minecraft:dark_oak_planks
setblock ~3 ~35 ~13 minecraft:dark_oak_planks
setblock ~3 ~35 ~14 minecraft:dark_oak_planks
setblock ~3 ~35 ~15 minecraft:dark_oak_planks
setblock ~3 ~36 ~11 minecraft:dark_oak_planks
setblock ~3 ~36 ~12 minecraft:dark_oak_planks
setblock ~3 ~36 ~13 minecraft:dark_oak_planks
setblock ~4 ~0 ~4 minecraft:mossy_cobblestone
setblock ~4 ~0 ~19 minecraft:cobblestone
setblock ~4 ~0 ~20 minecraft:mossy_cobblestone
setblock ~4 ~1 ~3 minecraft:oak_leaves[distance=7,persistent=true]
setblock ~4 ~1 ~4 minecraft:oak_leaves[distance=7,persistent=true]
setblock ~4 ~1 ~5 minecraft:cobblestone
setblock ~4 ~1 ~19 minecraft:cobblestone
setblock ~4 ~1 ~20 minecraft:mossy_cobblestone
setblock ~4 ~2 ~3 minecraft:oak_leaves[distance=7,persistent=true]
setblock ~4 ~2 ~4 minecraft:oak_leaves[distance=7,persistent=true]
setblock ~4 ~2 ~5 minecraft:mossy_stone_bricks
setblock ~4 ~2 ~6 minecraft:oak_leaves[distance=7,persistent=true]
setblock ~4 ~2 ~18 minecraft:mossy_cobblestone
setblock ~4 ~2 ~19 minecraft:mossy_cobblestone
setblock ~4 ~2 ~20 minecraft:cobblestone
setblock ~4 ~3 ~4 minecraft:oak_leaves[distance=7,persistent=true]
setblock ~4 ~3 ~5 minecraft:cobblestone
setblock ~4 ~3 ~6 minecraft:mossy_cobblestone
setblock ~4 ~3 ~18 minecraft:mossy_cobblestone
setblock ~4 ~3 ~19 minecraft:cobblestone
setblock ~4 ~4 ~4 minecraft:oak_leaves[distance=7,persistent=true]
setblock ~4 ~4 ~5 minecraft:oak_leaves[distance=7,persistent=true]
setblock ~4 ~4 ~6 minecraft:cobblestone
setblock ~4 ~4 ~18 minecraft:mossy_cobblestone
setblock ~4 ~4 ~19 minecraft:cobblestone
setblock ~4 ~5 ~4 minecraft:oak_leaves[distance=7,persistent=true]
setblock ~4 ~5 ~5 minecraft:cobblestone
setblock ~4 ~5 ~6 minecraft:mossy_cobblestone
setblock ~4 ~5 ~18 minecraft:cobblestone
setblock ~4 ~5 ~19 minecraft:cobblestone
setblock ~4 ~5 ~20 minecraft:mossy_cobblestone
setblock ~4 ~6 ~4 minecraft:oak_leaves[distance=7,persistent=true]
setblock ~4 ~6 ~5 minecraft:oak_leaves[distance=7,persistent=true]
setblock ~4 ~6 ~6 minecraft:mossy_cobblestone
setblock ~4 ~6 ~18 minecraft:cobblestone
setblock ~4 ~6 ~19 minecraft:stone_bricks
setblock ~4 ~7 ~5 minecraft:oak_leaves[distance=7,persistent=true]
setblock ~4 ~7 ~6 minecraft:mossy_stone_bricks
setblock ~4 ~7 ~18 minecraft:mossy_stone_bricks
setblock ~4 ~7 ~19 minecraft:mossy_cobblestone
setblock ~4 ~8 ~5 minecraft:oak_leaves[distance=7,persistent=true]
setblock ~4 ~8 ~6 minecraft:polished_blackstone
setblock ~4 ~8 ~18 minecraft:cobblestone
setblock ~4 ~8 ~19 minecraft:cobblestone
setblock ~4 ~9 ~5 minecraft:cobblestone
setblock ~4 ~9 ~6 minecraft:polished_blackstone
setblock ~4 ~9 ~18 minecraft:mossy_cobblestone
setblock ~4 ~9 ~19 minecraft:oak_leaves[distance=7,persistent=true]
setblock ~4 ~10 ~5 minecraft:stone_bricks
setblock ~4 ~10 ~6 minecraft:mossy_stone_bricks
setblock ~4 ~10 ~18 minecraft:cobblestone
setblock ~4 ~10 ~19 minecraft:oak_leaves[distance=7,persistent=true]
setblock ~4 ~10 ~20 minecraft:oak_leaves[distance=7,persistent=true]
setblock ~4 ~11 ~5 minecraft:polished_blackstone
setblock ~4 ~11 ~6 minecraft:polished_blackstone
setblock ~4 ~11 ~17 minecraft:polished_blackstone
setblock ~4 ~11 ~18 minecraft:polished_blackstone
setblock ~4 ~11 ~19 minecraft:oak_leaves[distance=7,persistent=true]
setblock ~4 ~12 ~4 minecraft:cobblestone
setblock ~4 ~12 ~5 minecraft:cobblestone
setblock ~4 ~12 ~6 minecraft:cobblestone
setblock ~4 ~12 ~17 minecraft:cobblestone
setblock ~4 ~12 ~18 minecraft:cobblestone
setblock ~4 ~12 ~19 minecraft:polished_blackstone
setblock ~4 ~12 ~20 minecraft:stone_bricks
setblock ~4 ~13 ~4 minecraft:cracked_stone_bricks
setblock ~4 ~13 ~5 minecraft:polished_blackstone
setblock ~4 ~13 ~6 minecraft:polished_blackstone
setblock ~4 ~13 ~7 minecraft:polished_blackstone
setblock ~4 ~13 ~17 minecraft:polished_blackstone
setblock ~4 ~13 ~18 minecraft:cobblestone
setblock ~4 ~13 ~19 minecraft:polished_blackstone
setblock ~4 ~14 ~5 minecraft:cobblestone
setblock ~4 ~14 ~6 minecraft:cobblestone
setblock ~4 ~14 ~7 minecraft:stone_bricks
setblock ~4 ~14 ~17 minecraft:cobblestone
setblock ~4 ~14 ~18 minecraft:cobblestone
setblock ~4 ~15 ~5 minecraft:stone_bricks
setblock ~4 ~15 ~6 minecraft:cobblestone
setblock ~4 ~15 ~7 minecraft:cobblestone
setblock ~4 ~15 ~17 minecraft:cobblestone
setblock ~4 ~15 ~18 minecraft:cobblestone
setblock ~4 ~16 ~5 minecraft:cobblestone
setblock ~4 ~16 ~6 minecraft:cobblestone
setblock ~4 ~16 ~7 minecraft:cobblestone
setblock ~4 ~16 ~17 minecraft:cracked_stone_bricks
setblock ~4 ~16 ~18 minecraft:cobblestone
setblock ~4 ~17 ~6 minecraft:cobblestone
setblock ~4 ~17 ~7 minecraft:cobblestone
setblock ~4 ~17 ~17 minecraft:cobblestone
setblock ~4 ~17 ~18 minecraft:cobblestone
setblock ~4 ~18 ~6 minecraft:stone_bricks
setblock ~4 ~18 ~7 minecraft:cobblestone
setblock ~4 ~18 ~17 minecraft:cobblestone
setblock ~4 ~18 ~18 minecraft:cobblestone
setblock ~4 ~19 ~6 minecraft:cracked_stone_bricks
setblock ~4 ~19 ~7 minecraft:cobblestone
setblock ~4 ~19 ~17 minecraft:cobblestone
setblock ~4 ~19 ~18 minecraft:cobblestone
setblock ~4 ~20 ~6 minecraft:cobblestone
setblock ~4 ~20 ~7 minecraft:cracked_stone_bricks
setblock ~4 ~20 ~17 minecraft:cobblestone
setblock ~4 ~20 ~18 minecraft:cobblestone
setblock ~4 ~21 ~5 minecraft:cobblestone
setblock ~4 ~21 ~6 minecraft:polished_blackstone
setblock ~4 ~21 ~7 minecraft:polished_blackstone
setblock ~4 ~21 ~17 minecraft:polished_blackstone
setblock ~4 ~21 ~18 minecraft:polished_blackstone
setblock ~4 ~21 ~19 minecraft:cobblestone
setblock ~4 ~22 ~5 minecraft:cobblestone
setblock ~4 ~22 ~6 minecraft:cobblestone
setblock ~4 ~22 ~7 minecraft:cobblestone
setblock ~4 ~22 ~17 minecraft:mossy_stone_bricks
setblock ~4 ~22 ~18 minecraft:cobblestone
setblock ~4 ~22 ~19 minecraft:cracked_stone_bricks
setblock ~4 ~23 ~6 minecraft:cobblestone
setblock ~4 ~23 ~7 minecraft:mossy_stone_bricks
setblock ~4 ~23 ~17 minecraft:cracked_stone_bricks
setblock ~4 ~23 ~18 minecraft:stone_bricks
setblock ~4 ~24 ~6 minecraft:cracked_stone_bricks
setblock ~4 ~24 ~7 minecraft:cobblestone
setblock ~4 ~24 ~17 minecraft:stone_bricks
setblock ~4 ~24 ~18 minecraft:cracked_stone_bricks
setblock ~4 ~25 ~6 minecraft:cobblestone
setblock ~4 ~25 ~7 minecraft:cobblestone
setblock ~4 ~25 ~12 minecraft:polished_blackstone
setblock ~4 ~25 ~16 minecraft:cobblestone
setblock ~4 ~25 ~17 minecraft:cobblestone
setblock ~4 ~25 ~18 minecraft:cobblestone
setblock ~4 ~26 ~6 minecraft:stone_bricks
setblock ~4 ~26 ~7 minecraft:cobblestone
setblock ~4 ~26 ~12 minecraft:polished_blackstone
setblock ~4 ~26 ~16 minecraft:cobblestone
setblock ~4 ~26 ~17 minecraft:cobblestone
setblock ~4 ~26 ~18 minecraft:stone_bricks
setblock ~4 ~27 ~6 minecraft:cobblestone
setblock ~4 ~27 ~7 minecraft:cobblestone
setblock ~4 ~27 ~8 minecraft:cobblestone
setblock ~4 ~27 ~12 minecraft:polished_blackstone
setblock ~4 ~27 ~16 minecraft:mossy_stone_bricks
setblock ~4 ~27 ~17 minecraft:cobblestone
setblock ~4 ~27 ~18 minecraft:cracked_stone_bricks
setblock ~4 ~28 ~6 minecraft:cobblestone
setblock ~4 ~28 ~7 minecraft:cobblestone
setblock ~4 ~28 ~16 minecraft:stone_bricks
setblock ~4 ~28 ~17 minecraft:cobblestone
setblock ~4 ~28 ~18 minecraft:cobblestone
setblock ~4 ~29 ~6 minecraft:polished_blackstone
setblock ~4 ~29 ~7 minecraft:polished_blackstone
setblock ~4 ~29 ~8 minecraft:polished_blackstone
setblock ~4 ~29 ~16 minecraft:polished_blackstone
setblock ~4 ~29 ~17 minecraft:polished_blackstone
setblock ~4 ~29 ~18 minecraft:polished_blackstone
setblock ~4 ~30 ~4 minecraft:spruce_planks
setblock ~4 ~30 ~5 minecraft:cobblestone
setblock ~4 ~30 ~6 minecraft:cobblestone
setblock ~4 ~30 ~7 minecraft:cobblestone
setblock ~4 ~30 ~8 minecraft:cobblestone
setblock ~4 ~30 ~9 minecraft:spruce_planks
setblock ~4 ~30 ~16 minecraft:cracked_stone_bricks
setblock ~4 ~30 ~17 minecraft:cobblestone
setblock ~4 ~30 ~18 minecraft:cobblestone
setblock ~4 ~30 ~19 minecraft:cobblestone
setblock ~4 ~30 ~20 minecraft:spruce_planks
setblock ~4 ~31 ~3 minecraft:dark_oak_planks
setblock ~4 ~31 ~4 minecraft:dark_oak_planks
setblock ~4 ~31 ~5 minecraft:dark_oak_planks
setblock ~4 ~31 ~6 minecraft:dark_oak_planks
setblock ~4 ~31 ~7 minecraft:dark_oak_planks
setblock ~4 ~31 ~8 minecraft:dark_oak_planks
setblock ~4 ~31 ~9 minecraft:dark_oak_planks
setblock ~4 ~31 ~15 minecraft:dark_oak_planks
setblock ~4 ~31 ~16 minecraft:dark_oak_planks
setblock ~4 ~31 ~17 minecraft:dark_oak_planks
setblock ~4 ~31 ~18 minecraft:dark_oak_planks
setblock ~4 ~31 ~19 minecraft:dark_oak_planks
setblock ~4 ~31 ~20 minecraft:dark_oak_planks
setblock ~4 ~31 ~21 minecraft:dark_oak_planks
setblock ~4 ~32 ~4 minecraft:dark_oak_planks
setblock ~4 ~32 ~5 minecraft:dark_oak_planks
setblock ~4 ~32 ~18 minecraft:dark_oak_planks
setblock ~4 ~32 ~19 minecraft:dark_oak_planks
setblock ~4 ~32 ~20 minecraft:dark_oak_planks
setblock ~4 ~33 ~5 minecraft:dark_oak_planks
setblock ~4 ~33 ~6 minecraft:dark_oak_planks
setblock ~4 ~33 ~7 minecraft:dark_oak_planks
setblock ~4 ~33 ~17 minecraft:dark_oak_planks
setblock ~4 ~33 ~18 minecraft:dark_oak_planks
setblock ~4 ~33 ~19 minecraft:dark_oak_planks
setblock ~4 ~34 ~6 minecraft:dark_oak_planks
setblock ~4 ~34 ~7 minecraft:dark_oak_planks
setblock ~4 ~34 ~8 minecraft:dark_oak_planks
setblock ~4 ~34 ~9 minecraft:dark_oak_planks
setblock ~4 ~34 ~15 minecraft:dark_oak_planks
setblock ~4 ~34 ~16 minecraft:dark_oak_planks
setblock ~4 ~34 ~17 minecraft:dark_oak_planks
setblock ~4 ~34 ~18 minecraft:dark_oak_planks
setblock ~4 ~35 ~7 minecraft:dark_oak_planks
setblock ~4 ~35 ~8 minecraft:dark_oak_planks
setblock ~4 ~35 ~9 minecraft:dark_oak_planks
setblock ~4 ~35 ~10 minecraft:dark_oak_planks
setblock ~4 ~35 ~11 minecraft:dark_oak_planks
setblock ~4 ~35 ~12 minecraft:dark_oak_planks
setblock ~4 ~35 ~13 minecraft:dark_oak_planks
setblock ~4 ~35 ~14 minecraft:dark_oak_planks
setblock ~4 ~35 ~15 minecraft:dark_oak_planks
setblock ~4 ~35 ~16 minecraft:dark_oak_planks
setblock ~4 ~35 ~17 minecraft:dark_oak_planks
setblock ~4 ~36 ~8 minecraft:dark_oak_planks
setblock ~4 ~36 ~9 minecraft:dark_oak_planks
setblock ~4 ~36 ~10 minecraft:dark_oak_planks
setblock ~4 ~36 ~11 minecraft:dark_oak_planks
setblock ~4 ~36 ~12 minecraft:dark_oak_planks
setblock ~4 ~36 ~13 minecraft:dark_oak_planks
setblock ~4 ~36 ~14 minecraft:dark_oak_planks
setblock ~4 ~36 ~15 minecraft:dark_oak_planks
setblock ~4 ~37 ~10 minecraft:dark_oak_planks
setblock ~4 ~37 ~11 minecraft:dark_oak_planks
setblock ~4 ~37 ~12 minecraft:dark_oak_planks
setblock ~4 ~37 ~13 minecraft:dark_oak_planks
setblock ~5 ~0 ~3 minecraft:mossy_cobblestone
setblock ~5 ~0 ~4 minecraft:mossy_cobblestone
setblock ~5 ~0 ~20 minecraft:cobblestone
setblock ~5 ~0 ~21 minecraft:mossy_cobblestone
setblock ~5 ~1 ~3 minecraft:oak_leaves[distance=7,persistent=true]
setblock ~5 ~1 ~4 minecraft:cobblestone
setblock ~5 ~1 ~20 minecraft:cobblestone
setblock ~5 ~2 ~3 minecraft:oak_leaves[distance=7,persistent=true]
setblock ~5 ~2 ~4 minecraft:cobblestone
setblock ~5 ~2 ~5 minecraft:mossy_cobblestone
setblock ~5 ~2 ~19 minecraft:mossy_cobblestone
setblock ~5 ~2 ~20 minecraft:mossy_cobblestone
setblock ~5 ~3 ~4 minecraft:stone_bricks
setblock ~5 ~3 ~5 minecraft:oak_leaves[distance=7,persistent=true]
setblock ~5 ~3 ~19 minecraft:cobblestone
setblock ~5 ~3 ~20 minecraft:cobblestone
setblock ~5 ~4 ~4 minecraft:oak_leaves[distance=7,persistent=true]
setblock ~5 ~4 ~5 minecraft:cobblestone
setblock ~5 ~4 ~19 minecraft:mossy_cobblestone
setblock ~5 ~4 ~20 minecraft:mossy_cobblestone
setblock ~5 ~5 ~3 minecraft:oak_leaves[distance=7,persistent=true]
setblock ~5 ~5 ~4 minecraft:oak_leaves[distance=7,persistent=true]
setblock ~5 ~5 ~5 minecraft:cobblestone
setblock ~5 ~5 ~19 minecraft:cobblestone
setblock ~5 ~5 ~20 minecraft:mossy_cobblestone
setblock ~5 ~5 ~21 minecraft:mossy_cobblestone
setblock ~5 ~6 ~4 minecraft:cobblestone
setblock ~5 ~6 ~5 minecraft:cobblestone
setblock ~5 ~6 ~19 minecraft:cobblestone
setblock ~5 ~6 ~20 minecraft:stone_bricks
setblock ~5 ~6 ~21 minecraft:mossy_cobblestone
setblock ~5 ~7 ~4 minecraft:mossy_cobblestone
setblock ~5 ~7 ~5 minecraft:mossy_cobblestone
setblock ~5 ~7 ~19 minecraft:mossy_cobblestone
setblock ~5 ~8 ~4 minecraft:stone_bricks
setblock ~5 ~8 ~5 minecraft:stone_bricks
setblock ~5 ~8 ~19 minecraft:mossy_cobblestone
setblock ~5 ~9 ~4 minecraft:cobblestone
setblock ~5 ~9 ~5 minecraft:cobblestone
setblock ~5 ~9 ~19 minecraft:cobblestone
setblock ~5 ~9 ~20 minecraft:oak_leaves[distance=7,persistent=true]
setblock ~5 ~10 ~4 minecraft:cobblestone
setblock ~5 ~10 ~5 minecraft:cobblestone
setblock ~5 ~10 ~19 minecraft:cobblestone
setblock ~5 ~10 ~20 minecraft:oak_leaves[distance=7,persistent=true]
setblock ~5 ~11 ~4 minecraft:polished_blackstone
setblock ~5 ~11 ~5 minecraft:polished_blackstone
setblock ~5 ~11 ~18 minecraft:polished_blackstone
setblock ~5 ~11 ~19 minecraft:cobblestone
setblock ~5 ~11 ~20 minecraft:oak_leaves[distance=7,persistent=true]
setblock ~5 ~12 ~3 minecraft:cobblestone
setblock ~5 ~12 ~4 minecraft:cobblestone
setblock ~5 ~12 ~5 minecraft:cobblestone
setblock ~5 ~12 ~18 minecraft:cobblestone
setblock ~5 ~12 ~19 minecraft:cobblestone
setblock ~5 ~12 ~20 minecraft:cobblestone
setblock ~5 ~13 ~4 minecraft:cobblestone
setblock ~5 ~13 ~5 minecraft:cobblestone
setblock ~5 ~13 ~18 minecraft:polished_blackstone
setblock ~5 ~13 ~19 minecraft:polished_blackstone
setblock ~5 ~13 ~20 minecraft:cobblestone
setblock ~5 ~14 ~5 minecraft:cobblestone
setblock ~5 ~14 ~6 minecraft:cobblestone
setblock ~5 ~14 ~18 minecraft:stone_bricks
setblock ~5 ~14 ~19 minecraft:mossy_stone_bricks
setblock ~5 ~15 ~5 minecraft:cobblestone
setblock ~5 ~15 ~18 minecraft:cobblestone
setblock ~5 ~15 ~19 minecraft:stone_bricks
setblock ~5 ~16 ~5 minecraft:cobblestone
setblock ~5 ~16 ~6 minecraft:cobblestone
setblock ~5 ~16 ~18 minecraft:mossy_stone_bricks
setblock ~5 ~16 ~19 minecraft:cracked_stone_bricks
setblock ~5 ~17 ~5 minecraft:cobblestone
setblock ~5 ~17 ~6 minecraft:cobblestone
setblock ~5 ~17 ~18 minecraft:cracked_stone_bricks
setblock ~5 ~17 ~19 minecraft:cobblestone
setblock ~5 ~18 ~5 minecraft:mossy_stone_bricks
setblock ~5 ~18 ~6 minecraft:cobblestone
setblock ~5 ~18 ~18 minecraft:cobblestone
setblock ~5 ~18 ~19 minecraft:cracked_stone_bricks
setblock ~5 ~19 ~5 minecraft:cobblestone
setblock ~5 ~19 ~6 minecraft:cobblestone
setblock ~5 ~19 ~18 minecraft:cobblestone
setblock ~5 ~19 ~19 minecraft:cobblestone
setblock ~5 ~20 ~5 minecraft:polished_blackstone
setblock ~5 ~20 ~6 minecraft:stone_bricks
setblock ~5 ~20 ~18 minecraft:cobblestone
setblock ~5 ~20 ~19 minecraft:polished_blackstone
setblock ~5 ~21 ~4 minecraft:cobblestone
setblock ~5 ~21 ~5 minecraft:polished_blackstone
setblock ~5 ~21 ~6 minecraft:polished_blackstone
setblock ~5 ~21 ~18 minecraft:polished_blackstone
setblock ~5 ~21 ~19 minecraft:cobblestone
setblock ~5 ~21 ~20 minecraft:cobblestone
setblock ~5 ~22 ~4 minecraft:stone_bricks
setblock ~5 ~22 ~5 minecraft:cobblestone
setblock ~5 ~22 ~6 minecraft:cracked_stone_bricks
setblock ~5 ~22 ~18 minecraft:cobblestone
setblock ~5 ~22 ~19 minecraft:cobblestone
setblock ~5 ~22 ~20 minecraft:cobblestone
setblock ~5 ~23 ~5 minecraft:cobblestone
setblock ~5 ~23 ~6 minecraft:cobblestone
setblock ~5 ~23 ~18 minecraft:cobblestone
setblock ~5 ~23 ~19 minecraft:cobblestone
setblock ~5 ~24 ~5 minecraft:cobblestone
setblock ~5 ~24 ~6 minecraft:cobblestone
setblock ~5 ~24 ~18 minecraft:cobblestone
setblock ~5 ~24 ~19 minecraft:cobblestone
setblock ~5 ~25 ~5 minecraft:cobblestone
setblock ~5 ~25 ~6 minecraft:cobblestone
setblock ~5 ~25 ~18 minecraft:cobblestone
setblock ~5 ~25 ~19 minecraft:cobblestone
setblock ~5 ~26 ~5 minecraft:cobblestone
setblock ~5 ~26 ~6 minecraft:cobblestone
setblock ~5 ~26 ~18 minecraft:cracked_stone_bricks
setblock ~5 ~27 ~5 minecraft:cobblestone
setblock ~5 ~27 ~6 minecraft:cobblestone
setblock ~5 ~27 ~18 minecraft:cobblestone
setblock ~5 ~28 ~5 minecraft:cobblestone
setblock ~5 ~28 ~6 minecraft:stone_bricks
setblock ~5 ~28 ~17 minecraft:cobblestone
setblock ~5 ~28 ~18 minecraft:cobblestone
setblock ~5 ~29 ~5 minecraft:polished_blackstone
setblock ~5 ~29 ~6 minecraft:polished_blackstone
setblock ~5 ~29 ~7 minecraft:polished_blackstone
setblock ~5 ~29 ~17 minecraft:polished_blackstone
setblock ~5 ~29 ~18 minecraft:polished_blackstone
setblock ~5 ~29 ~19 minecraft:polished_blackstone
setblock ~5 ~30 ~3 minecraft:spruce_planks
setblock ~5 ~30 ~4 minecraft:spruce_planks
setblock ~5 ~30 ~5 minecraft:cobblestone
setblock ~5 ~30 ~6 minecraft:cobblestone
setblock ~5 ~30 ~7 minecraft:cobblestone
setblock ~5 ~30 ~17 minecraft:cobblestone
setblock ~5 ~30 ~18 minecraft:cobblestone
setblock ~5 ~30 ~19 minecraft:cobblestone
setblock ~5 ~30 ~20 minecraft:spruce_planks
setblock ~5 ~30 ~21 minecraft:spruce_planks
setblock ~5 ~31 ~2 minecraft:dark_oak_planks
setblock ~5 ~31 ~3 minecraft:dark_oak_planks
setblock ~5 ~31 ~4 minecraft:dark_oak_planks
setblock ~5 ~31 ~5 minecraft:dark_oak_planks
setblock ~5 ~31 ~6 minecraft:dark_oak_planks
setblock ~5 ~31 ~7 minecraft:dark_oak_planks
setblock ~5 ~31 ~17 minecraft:dark_oak_planks
setblock ~5 ~31 ~18 minecraft:dark_oak_planks
setblock ~5 ~31 ~19 minecraft:dark_oak_planks
setblock ~5 ~31 ~20 minecraft:dark_oak_planks
setblock ~5 ~31 ~21 minecraft:dark_oak_planks
setblock ~5 ~32 ~3 minecraft:dark_oak_planks
setblock ~5 ~32 ~4 minecraft:dark_oak_planks
setblock ~5 ~32 ~5 minecraft:dark_oak_planks
setblock ~5 ~32 ~19 minecraft:dark_oak_planks
setblock ~5 ~32 ~20 minecraft:dark_oak_planks
setblock ~5 ~32 ~21 minecraft:dark_oak_planks
setblock ~5 ~33 ~4 minecraft:dark_oak_planks
setblock ~5 ~33 ~5 minecraft:dark_oak_planks
setblock ~5 ~33 ~6 minecraft:dark_oak_planks
setblock ~5 ~33 ~18 minecraft:dark_oak_planks
setblock ~5 ~33 ~19 minecraft:dark_oak_planks
setblock ~5 ~33 ~20 minecraft:dark_oak_planks
setblock ~5 ~34 ~5 minecraft:dark_oak_planks
setblock ~5 ~34 ~6 minecraft:dark_oak_planks
setblock ~5 ~34 ~7 minecraft:dark_oak_planks
setblock ~5 ~34 ~17 minecraft:dark_oak_planks
setblock ~5 ~34 ~18 minecraft:dark_oak_planks
setblock ~5 ~34 ~19 minecraft:dark_oak_planks
setblock ~5 ~35 ~6 minecraft:dark_oak_planks
setblock ~5 ~35 ~7 minecraft:dark_oak_planks
setblock ~5 ~35 ~8 minecraft:dark_oak_planks
setblock ~5 ~35 ~15 minecraft:dark_oak_planks
setblock ~5 ~35 ~16 minecraft:dark_oak_planks
setblock ~5 ~35 ~17 minecraft:dark_oak_planks
setblock ~5 ~35 ~18 minecraft:dark_oak_planks
setblock ~5 ~36 ~7 minecraft:dark_oak_planks
setblock ~5 ~36 ~8 minecraft:dark_oak_planks
setblock ~5 ~36 ~9 minecraft:dark_oak_planks
setblock ~5 ~36 ~10 minecraft:dark_oak_planks
setblock ~5 ~36 ~11 minecraft:dark_oak_planks
setblock ~5 ~36 ~12 minecraft:dark_oak_planks
setblock ~5 ~36 ~13 minecraft:dark_oak_planks
setblock ~5 ~36 ~14 minecraft:dark_oak_planks
setblock ~5 ~36 ~15 minecraft:dark_oak_planks
setblock ~5 ~36 ~16 minecraft:dark_oak_planks
setblock ~5 ~36 ~17 minecraft:dark_oak_planks
setblock ~5 ~37 ~9 minecraft:dark_oak_planks
setblock ~5 ~37 ~10 minecraft:dark_oak_planks
setblock ~5 ~37 ~11 minecraft:dark_oak_planks
setblock ~5 ~37 ~12 minecraft:dark_oak_planks
setblock ~5 ~37 ~13 minecraft:dark_oak_planks
setblock ~5 ~37 ~14 minecraft:dark_oak_planks
setblock ~5 ~37 ~15 minecraft:dark_oak_planks
setblock ~5 ~38 ~10 minecraft:dark_oak_planks
setblock ~5 ~38 ~11 minecraft:dark_oak_planks
setblock ~5 ~38 ~12 minecraft:dark_oak_planks
setblock ~5 ~38 ~13 minecraft:dark_oak_planks
setblock ~5 ~38 ~14 minecraft:dark_oak_planks
setblock ~6 ~0 ~2 minecraft:mossy_cobblestone
setblock ~6 ~0 ~3 minecraft:mossy_cobblestone
setblock ~6 ~0 ~21 minecraft:mossy_cobblestone
setblock ~6 ~1 ~3 minecraft:cracked_stone_bricks
setblock ~6 ~1 ~20 minecraft:mossy_cobblestone
setblock ~6 ~1 ~21 minecraft:cobblestone
setblock ~6 ~2 ~3 minecraft:mossy_cobblestone
setblock ~6 ~2 ~4 minecraft:mossy_cobblestone
setblock ~6 ~2 ~20 minecraft:mossy_cobblestone
setblock ~6 ~2 ~21 minecraft:cobblestone
setblock ~6 ~3 ~3 minecraft:mossy_cobblestone
setblock ~6 ~3 ~4 minecraft:mossy_stone_bricks
setblock ~6 ~3 ~20 minecraft:mossy_cobblestone
setblock ~6 ~3 ~21 minecraft:oak_leaves[distance=7,persistent=true]
setblock ~6 ~4 ~3 minecraft:mossy_cobblestone
setblock ~6 ~4 ~4 minecraft:mossy_cobblestone
setblock ~6 ~4 ~20 minecraft:mossy_cobblestone
setblock ~6 ~4 ~21 minecraft:oak_leaves[distance=7,persistent=true]
setblock ~6 ~5 ~4 minecraft:stone_bricks
setblock ~6 ~5 ~19 minecraft:cobblestone
setblock ~6 ~5 ~20 minecraft:cobblestone
setblock ~6 ~5 ~21 minecraft:mossy_stone_bricks
setblock ~6 ~6 ~4 minecraft:cobblestone
setblock ~6 ~6 ~19 minecraft:mossy_cobblestone
setblock ~6 ~6 ~20 minecraft:mossy_cobblestone
setblock ~6 ~6 ~21 minecraft:mossy_cobblestone
setblock ~6 ~7 ~4 minecraft:cracked_stone_bricks
setblock ~6 ~7 ~19 minecraft:mossy_cobblestone
setblock ~6 ~7 ~21 minecraft:oak_leaves[distance=7,persistent=true]
setblock ~6 ~8 ~3 minecraft:oak_leaves[distance=7,persistent=true]
setblock ~6 ~8 ~4 minecraft:cobblestone
setblock ~6 ~8 ~19 minecraft:mossy_cobblestone
setblock ~6 ~8 ~20 minecraft:oak_leaves[distance=7,persistent=true]
setblock ~6 ~8 ~21 minecraft:oak_leaves[distance=7,persistent=true]
setblock ~6 ~9 ~3 minecraft:oak_leaves[distance=7,persistent=true]
setblock ~6 ~9 ~4 minecraft:mossy_stone_bricks
setblock ~6 ~9 ~19 minecraft:cobblestone
setblock ~6 ~9 ~20 minecraft:mossy_cobblestone
setblock ~6 ~9 ~21 minecraft:cobblestone
setblock ~6 ~10 ~3 minecraft:oak_leaves[distance=7,persistent=true]
setblock ~6 ~10 ~4 minecraft:cracked_stone_bricks
setblock ~6 ~10 ~19 minecraft:stone_bricks
setblock ~6 ~10 ~20 minecraft:cobblestone
setblock ~6 ~10 ~21 minecraft:cobblestone
setblock ~6 ~11 ~3 minecraft:cobblestone
setblock ~6 ~11 ~4 minecraft:polished_blackstone
setblock ~6 ~11 ~5 minecraft:polished_blackstone
setblock ~6 ~11 ~19 minecraft:polished_blackstone
setblock ~6 ~11 ~20 minecraft:polished_blackstone
setblock ~6 ~12 ~3 minecraft:cobblestone
setblock ~6 ~12 ~4 minecraft:stone_bricks
setblock ~6 ~12 ~5 minecraft:cobblestone
setblock ~6 ~12 ~19 minecraft:cobblestone
setblock ~6 ~12 ~20 minecraft:cobblestone
setblock ~6 ~12 ~21 minecraft:cobblestone
setblock ~6 ~13 ~3 minecraft:cobblestone
setblock ~6 ~13 ~4 minecraft:polished_blackstone
setblock ~6 ~13 ~5 minecraft:polished_blackstone
setblock ~6 ~13 ~19 minecraft:polished_blackstone
setblock ~6 ~13 ~20 minecraft:polished_blackstone
setblock ~6 ~13 ~21 minecraft:cobblestone
setblock ~6 ~14 ~4 minecraft:cobblestone
setblock ~6 ~14 ~5 minecraft:cobblestone
setblock ~6 ~14 ~19 minecraft:cobblestone
setblock ~6 ~14 ~20 minecraft:stone_bricks
setblock ~6 ~15 ~4 minecraft:cobblestone
setblock ~6 ~15 ~5 minecraft:cobblestone
setblock ~6 ~15 ~19 minecraft:cobblestone
setblock ~6 ~15 ~20 minecraft:cobblestone
setblock ~6 ~16 ~4 minecraft:cobblestone
setblock ~6 ~16 ~5 minecraft:cobblestone
setblock ~6 ~16 ~19 minecraft:cobblestone
setblock ~6 ~16 ~20 minecraft:cobblestone
setblock ~6 ~17 ~4 minecraft:cobblestone
setblock ~6 ~17 ~5 minecraft:cobblestone
setblock ~6 ~17 ~19 minecraft:cobblestone
setblock ~6 ~17 ~20 minecraft:cobblestone
setblock ~6 ~18 ~4 minecraft:cobblestone
setblock ~6 ~18 ~5 minecraft:cobblestone
setblock ~6 ~18 ~19 minecraft:cobblestone
setblock ~6 ~19 ~4 minecraft:cobblestone
setblock ~6 ~19 ~5 minecraft:cobblestone
setblock ~6 ~19 ~19 minecraft:cobblestone
setblock ~6 ~20 ~4 minecraft:polished_blackstone
setblock ~6 ~20 ~5 minecraft:cobblestone
setblock ~6 ~20 ~19 minecraft:mossy_stone_bricks
setblock ~6 ~20 ~20 minecraft:polished_blackstone
setblock ~6 ~21 ~3 minecraft:cobblestone
setblock ~6 ~21 ~4 minecraft:cobblestone
setblock ~6 ~21 ~5 minecraft:polished_blackstone
setblock ~6 ~21 ~19 minecraft:polished_blackstone
setblock ~6 ~21 ~20 minecraft:cobblestone
setblock ~6 ~22 ~3 minecraft:cobblestone
setblock ~6 ~22 ~4 minecraft:cobblestone
setblock ~6 ~22 ~5 minecraft:cobblestone
setblock ~6 ~22 ~19 minecraft:cobblestone
setblock ~6 ~22 ~20 minecraft:cobblestone
setblock ~6 ~23 ~4 minecraft:cobblestone
setblock ~6 ~23 ~5 minecraft:cobblestone
setblock ~6 ~23 ~19 minecraft:cobblestone
setblock ~6 ~24 ~5 minecraft:cobblestone
setblock ~6 ~24 ~18 minecraft:cobblestone
setblock ~6 ~24 ~19 minecraft:cobblestone
setblock ~6 ~25 ~5 minecraft:cracked_stone_bricks
setblock ~6 ~25 ~18 minecraft:cobblestone
setblock ~6 ~25 ~19 minecraft:cobblestone
setblock ~6 ~26 ~5 minecraft:stone_bricks
setblock ~6 ~26 ~18 minecraft:cobblestone
setblock ~6 ~26 ~19 minecraft:cobblestone
setblock ~6 ~27 ~5 minecraft:stone_bricks
setblock ~6 ~27 ~18 minecraft:cobblestone
setblock ~6 ~27 ~19 minecraft:cobblestone
setblock ~6 ~28 ~5 minecraft:cobblestone
setblock ~6 ~28 ~18 minecraft:cobblestone
setblock ~6 ~28 ~19 minecraft:cobblestone
setblock ~6 ~29 ~5 minecraft:polished_blackstone
setblock ~6 ~29 ~6 minecraft:polished_blackstone
setblock ~6 ~29 ~18 minecraft:polished_blackstone
setblock ~6 ~29 ~19 minecraft:polished_blackstone
setblock ~6 ~30 ~3 minecraft:spruce_planks
setblock ~6 ~30 ~4 minecraft:cobblestone
setblock ~6 ~30 ~5 minecraft:mossy_stone_bricks
setblock ~6 ~30 ~6 minecraft:spruce_planks
setblock ~6 ~30 ~18 minecraft:cobblestone
setblock ~6 ~30 ~19 minecraft:cobblestone
setblock ~6 ~30 ~20 minecraft:cobblestone
setblock ~6 ~30 ~21 minecraft:spruce_planks
setblock ~6 ~31 ~2 minecraft:dark_oak_planks
setblock ~6 ~31 ~3 minecraft:dark_oak_planks
setblock ~6 ~31 ~4 minecraft:dark_oak_planks
setblock ~6 ~31 ~5 minecraft:dark_oak_planks
setblock ~6 ~31 ~6 minecraft:dark_oak_planks
setblock ~6 ~31 ~18 minecraft:dark_oak_planks
setblock ~6 ~31 ~19 minecraft:dark_oak_planks
setblock ~6 ~31 ~20 minecraft:dark_oak_planks
setblock ~6 ~31 ~21 minecraft:dark_oak_planks
setblock ~6 ~31 ~22 minecraft:dark_oak_planks
setblock ~6 ~32 ~3 minecraft:dark_oak_planks
setblock ~6 ~32 ~4 minecraft:dark_oak_planks
setblock ~6 ~32 ~20 minecraft:dark_oak_planks
setblock ~6 ~32 ~21 minecraft:dark_oak_planks
setblock ~6 ~33 ~3 minecraft:dark_oak_planks
setblock ~6 ~33 ~4 minecraft:dark_oak_planks
setblock ~6 ~33 ~5 minecraft:dark_oak_planks
setblock ~6 ~33 ~19 minecraft:dark_oak_planks
setblock ~6 ~33 ~20 minecraft:dark_oak_planks
setblock ~6 ~34 ~4 minecraft:dark_oak_planks
setblock ~6 ~34 ~5 minecraft:dark_oak_planks
setblock ~6 ~34 ~6 minecraft:dark_oak_planks
setblock ~6 ~34 ~18 minecraft:dark_oak_planks
setblock ~6 ~34 ~19 minecraft:dark_oak_planks
setblock ~6 ~35 ~5 minecraft:dark_oak_planks
setblock ~6 ~35 ~6 minecraft:dark_oak_planks
setblock ~6 ~35 ~7 minecraft:dark_oak_planks
setblock ~6 ~35 ~17 minecraft:dark_oak_planks
setblock ~6 ~35 ~18 minecraft:dark_oak_planks
setblock ~6 ~36 ~6 minecraft:dark_oak_planks
setblock ~6 ~36 ~7 minecraft:dark_oak_planks
setblock ~6 ~36 ~8 minecraft:dark_oak_planks
setblock ~6 ~36 ~9 minecraft:dark_oak_planks
setblock ~6 ~36 ~15 minecraft:dark_oak_planks
setblock ~6 ~36 ~16 minecraft:dark_oak_planks
setblock ~6 ~36 ~17 minecraft:dark_oak_planks
setblock ~6 ~37 ~7 minecraft:dark_oak_planks
setblock ~6 ~37 ~8 minecraft:dark_oak_planks
setblock ~6 ~37 ~9 minecraft:dark_oak_planks
setblock ~6 ~37 ~10 minecraft:dark_oak_planks
setblock ~6 ~37 ~11 minecraft:dark_oak_planks
setblock ~6 ~37 ~13 minecraft:dark_oak_planks
setblock ~6 ~37 ~14 minecraft:dark_oak_planks
setblock ~6 ~37 ~15 minecraft:dark_oak_planks
setblock ~6 ~37 ~16 minecraft:dark_oak_planks
setblock ~6 ~38 ~9 minecraft:dark_oak_planks
setblock ~6 ~38 ~10 minecraft:dark_oak_planks
setblock ~6 ~38 ~11 minecraft:dark_oak_planks
setblock ~6 ~38 ~12 minecraft:dark_oak_planks
setblock ~6 ~38 ~13 minecraft:dark_oak_planks
setblock ~6 ~38 ~14 minecraft:dark_oak_planks
setblock ~6 ~38 ~15 minecraft:dark_oak_planks
setblock ~6 ~39 ~10 minecraft:dark_oak_planks
setblock ~6 ~39 ~11 minecraft:dark_oak_planks
setblock ~6 ~39 ~12 minecraft:dark_oak_planks
setblock ~6 ~39 ~13 minecraft:dark_oak_planks
setblock ~6 ~39 ~14 minecraft:dark_oak_planks
setblock ~7 ~0 ~2 minecraft:mossy_cobblestone
setblock ~7 ~0 ~3 minecraft:cobblestone
setblock ~7 ~0 ~12 minecraft:cobblestone
setblock ~7 ~0 ~13 minecraft:cobblestone
setblock ~7 ~0 ~14 minecraft:mossy_cobblestone
setblock ~7 ~0 ~21 minecraft:mossy_cobblestone
setblock ~7 ~0 ~22 minecraft:mossy_cobblestone
setblock ~7 ~1 ~2 minecraft:mossy_cobblestone
setblock ~7 ~1 ~3 minecraft:mossy_cobblestone
setblock ~7 ~1 ~12 minecraft:mossy_cobblestone
setblock ~7 ~1 ~13 minecraft:mossy_cobblestone
setblock ~7 ~1 ~14 minecraft:mossy_cobblestone
setblock ~7 ~1 ~21 minecraft:mossy_cobblestone
setblock ~7 ~2 ~3 minecraft:mossy_cobblestone
setblock ~7 ~2 ~4 minecraft:mossy_cobblestone
setblock ~7 ~2 ~12 minecraft:mossy_cobblestone
setblock ~7 ~2 ~13 minecraft:mossy_cobblestone
setblock ~7 ~2 ~14 minecraft:mossy_cobblestone
setblock ~7 ~2 ~20 minecraft:mossy_cobblestone
setblock ~7 ~2 ~21 minecraft:oak_leaves[distance=7,persistent=true]
setblock ~7 ~3 ~3 minecraft:mossy_cobblestone
setblock ~7 ~3 ~4 minecraft:cobblestone
setblock ~7 ~3 ~12 minecraft:mossy_cobblestone
setblock ~7 ~3 ~13 minecraft:cobblestone
setblock ~7 ~3 ~14 minecraft:mossy_cobblestone
setblock ~7 ~3 ~20 minecraft:mossy_cobblestone
setblock ~7 ~3 ~21 minecraft:oak_leaves[distance=7,persistent=true]
setblock ~7 ~4 ~3 minecraft:mossy_cobblestone
setblock ~7 ~4 ~4 minecraft:mossy_cobblestone
setblock ~7 ~4 ~12 minecraft:cobblestone
setblock ~7 ~4 ~13 minecraft:stone_bricks
setblock ~7 ~4 ~14 minecraft:mossy_cobblestone
setblock ~7 ~4 ~20 minecraft:mossy_cobblestone
setblock ~7 ~4 ~21 minecraft:oak_leaves[distance=7,persistent=true]
setblock ~7 ~4 ~22 minecraft:oak_leaves[distance=7,persistent=true]
setblock ~7 ~5 ~2 minecraft:mossy_cobblestone
setblock ~7 ~5 ~3 minecraft:cobblestone
setblock ~7 ~5 ~4 minecraft:mossy_cobblestone
setblock ~7 ~5 ~12 minecraft:cobblestone
setblock ~7 ~5 ~13 minecraft:mossy_cobblestone
setblock ~7 ~5 ~14 minecraft:mossy_stone_bricks
setblock ~7 ~5 ~20 minecraft:mossy_cobblestone
setblock ~7 ~5 ~21 minecraft:oak_leaves[distance=7,persistent=true]
setblock ~7 ~5 ~22 minecraft:mossy_cobblestone
setblock ~7 ~6 ~2 minecraft:cobblestone
setblock ~7 ~6 ~3 minecraft:oak_leaves[distance=7,persistent=true]
setblock ~7 ~6 ~4 minecraft:cobblestone
setblock ~7 ~6 ~12 minecraft:stone_bricks
setblock ~7 ~6 ~13 minecraft:cobblestone
setblock ~7 ~6 ~14 minecraft:cobblestone
setblock ~7 ~6 ~20 minecraft:cobblestone
setblock ~7 ~6 ~21 minecraft:cobblestone
setblock ~7 ~6 ~22 minecraft:cobblestone
setblock ~7 ~7 ~2 minecraft:oak_leaves[distance=7,persistent=true]
setblock ~7 ~7 ~3 minecraft:oak_leaves[distance=7,persistent=true]
setblock ~7 ~7 ~4 minecraft:cobblestone
setblock ~7 ~7 ~20 minecraft:oak_leaves[distance=7,persistent=true]
setblock ~7 ~7 ~21 minecraft:oak_leaves[distance=7,persistent=true]
setblock ~7 ~8 ~2 minecraft:oak_leaves[distance=7,persistent=true]
setblock ~7 ~8 ~3 minecraft:oak_leaves[distance=7,persistent=true]
setblock ~7 ~8 ~4 minecraft:stone_bricks
setblock ~7 ~8 ~20 minecraft:oak_leaves[distance=7,persistent=true]
setblock ~7 ~8 ~21 minecraft:oak_leaves[distance=7,persistent=true]
setblock ~7 ~9 ~3 minecraft:oak_leaves[distance=7,persistent=true]
setblock ~7 ~9 ~4 minecraft:mossy_cobblestone
setblock ~7 ~9 ~20 minecraft:cobblestone
setblock ~7 ~9 ~21 minecraft:cobblestone
setblock ~7 ~10 ~2 minecraft:oak_leaves[distance=7,persistent=true]
setblock ~7 ~10 ~3 minecraft:oak_leaves[distance=7,persistent=true]
setblock ~7 ~10 ~4 minecraft:cobblestone
setblock ~7 ~10 ~19 minecraft:stone_bricks
setblock ~7 ~10 ~20 minecraft:cobblestone
setblock ~7 ~10 ~21 minecraft:cobblestone
setblock ~7 ~11 ~3 minecraft:oak_leaves[distance=7,persistent=true]
setblock ~7 ~11 ~4 minecraft:polished_blackstone
setblock ~7 ~11 ~20 minecraft:cobblestone
setblock ~7 ~11 ~21 minecraft:cracked_stone_bricks
setblock ~7 ~12 ~3 minecraft:cracked_stone_bricks
setblock ~7 ~12 ~4 minecraft:cobblestone
setblock ~7 ~12 ~20 minecraft:cobblestone
setblock ~7 ~12 ~21 minecraft:cobblestone
setblock ~7 ~13 ~3 minecraft:stone_bricks
setblock ~7 ~13 ~4 minecraft:polished_blackstone
setblock ~7 ~13 ~20 minecraft:cobblestone
setblock ~7 ~13 ~21 minecraft:cracked_stone_bricks
setblock ~7 ~14 ~4 minecraft:cobblestone
setblock ~7 ~14 ~20 minecraft:cobblestone
setblock ~7 ~14 ~21 minecraft:cobblestone
setblock ~7 ~14 ~22 minecraft:cobblestone
setblock ~7 ~15 ~4 minecraft:cobblestone
setblock ~7 ~15 ~20 minecraft:stone_bricks
setblock ~7 ~15 ~21 minecraft:cobblestone
setblock ~7 ~16 ~4 minecraft:cobblestone
setblock ~7 ~16 ~20 minecraft:cobblestone
setblock ~7 ~17 ~4 minecraft:cobblestone
setblock ~7 ~17 ~19 minecraft:cobblestone
setblock ~7 ~17 ~20 minecraft:cobblestone
setblock ~7 ~18 ~4 minecraft:cobblestone
setblock ~7 ~18 ~19 minecraft:cobblestone
setblock ~7 ~18 ~20 minecraft:cobblestone
setblock ~7 ~19 ~4 minecraft:cobblestone
setblock ~7 ~19 ~19 minecraft:cobblestone
setblock ~7 ~19 ~20 minecraft:cobblestone
setblock ~7 ~20 ~4 minecraft:cracked_stone_bricks
setblock ~7 ~20 ~5 minecraft:polished_blackstone
setblock ~7 ~20 ~19 minecraft:polished_blackstone
setblock ~7 ~20 ~20 minecraft:polished_blackstone
setblock ~7 ~21 ~3 minecraft:cracked_stone_bricks
setblock ~7 ~21 ~4 minecraft:polished_blackstone
setblock ~7 ~21 ~5 minecraft:polished_blackstone
setblock ~7 ~21 ~19 minecraft:polished_blackstone
setblock ~7 ~21 ~20 minecraft:polished_blackstone
setblock ~7 ~21 ~21 minecraft:mossy_stone_bricks
setblock ~7 ~22 ~3 minecraft:cobblestone
setblock ~7 ~22 ~4 minecraft:stone_bricks
setblock ~7 ~22 ~5 minecraft:stone_bricks
setblock ~7 ~22 ~19 minecraft:cobblestone
setblock ~7 ~22 ~20 minecraft:cobblestone
setblock ~7 ~22 ~21 minecraft:cobblestone
setblock ~7 ~23 ~3 minecraft:cobblestone
setblock ~7 ~23 ~4 minecraft:cobblestone
setblock ~7 ~23 ~5 minecraft:cobblestone
setblock ~7 ~23 ~19 minecraft:cobblestone
setblock ~7 ~23 ~20 minecraft:cobblestone
setblock ~7 ~23 ~21 minecraft:cobblestone
setblock ~7 ~24 ~3 minecraft:cobblestone
setblock ~7 ~24 ~4 minecraft:cobblestone
setblock ~7 ~24 ~5 minecraft:cobblestone
setblock ~7 ~24 ~19 minecraft:cobblestone
setblock ~7 ~24 ~20 minecraft:cobblestone
setblock ~7 ~24 ~21 minecraft:stone_bricks
setblock ~7 ~25 ~4 minecraft:cobblestone
setblock ~7 ~25 ~5 minecraft:cobblestone
setblock ~7 ~25 ~19 minecraft:cobblestone
setblock ~7 ~25 ~20 minecraft:cobblestone
setblock ~7 ~26 ~4 minecraft:cobblestone
setblock ~7 ~26 ~5 minecraft:cobblestone
setblock ~7 ~26 ~19 minecraft:cobblestone
setblock ~7 ~26 ~20 minecraft:cracked_stone_bricks
setblock ~7 ~27 ~4 minecraft:cobblestone
setblock ~7 ~27 ~5 minecraft:cobblestone
setblock ~7 ~27 ~19 minecraft:cobblestone
setblock ~7 ~28 ~4 minecraft:cobblestone
setblock ~7 ~28 ~5 minecraft:cobblestone
setblock ~7 ~28 ~19 minecraft:cobblestone
setblock ~7 ~29 ~4 minecraft:polished_blackstone
setblock ~7 ~29 ~5 minecraft:polished_blackstone
setblock ~7 ~29 ~19 minecraft:polished_blackstone
setblock ~7 ~29 ~20 minecraft:polished_blackstone
setblock ~7 ~30 ~2 minecraft:spruce_planks
setblock ~7 ~30 ~3 minecraft:spruce_planks
setblock ~7 ~30 ~4 minecraft:cobblestone
setblock ~7 ~30 ~5 minecraft:cobblestone
setblock ~7 ~30 ~18 minecraft:spruce_planks
setblock ~7 ~30 ~19 minecraft:cobblestone
setblock ~7 ~30 ~20 minecraft:cobblestone
setblock ~7 ~30 ~21 minecraft:spruce_planks
setblock ~7 ~31 ~2 minecraft:dark_oak_planks
setblock ~7 ~31 ~3 minecraft:dark_oak_planks
setblock ~7 ~31 ~4 minecraft:dark_oak_planks
setblock ~7 ~31 ~5 minecraft:dark_oak_planks
setblock ~7 ~31 ~18 minecraft:dark_oak_planks
setblock ~7 ~31 ~19 minecraft:dark_oak_planks
setblock ~7 ~31 ~20 minecraft:dark_oak_planks
setblock ~7 ~31 ~21 minecraft:dark_oak_planks
setblock ~7 ~31 ~22 minecraft:dark_oak_planks
setblock ~7 ~32 ~2 minecraft:dark_oak_planks
setblock ~7 ~32 ~3 minecraft:dark_oak_planks
setblock ~7 ~32 ~20 minecraft:dark_oak_planks
setblock ~7 ~32 ~21 minecraft:dark_oak_planks
setblock ~7 ~32 ~22 minecraft:dark_oak_planks
setblock ~7 ~33 ~3 minecraft:dark_oak_planks
setblock ~7 ~33 ~4 minecraft:dark_oak_planks
setblock ~7 ~33 ~19 minecraft:dark_oak_planks
setblock ~7 ~33 ~20 minecraft:dark_oak_planks
setblock ~7 ~33 ~21 minecraft:dark_oak_planks
setblock ~7 ~34 ~4 minecraft:dark_oak_planks
setblock ~7 ~34 ~5 minecraft:dark_oak_planks
setblock ~7 ~34 ~18 minecraft:dark_oak_planks
setblock ~7 ~34 ~19 minecraft:dark_oak_planks
setblock ~7 ~34 ~20 minecraft:dark_oak_planks
setblock ~7 ~35 ~5 minecraft:dark_oak_planks
setblock ~7 ~35 ~6 minecraft:dark_oak_planks
setblock ~7 ~35 ~17 minecraft:dark_oak_planks
setblock ~7 ~35 ~18 minecraft:dark_oak_planks
setblock ~7 ~35 ~19 minecraft:dark_oak_planks
setblock ~7 ~36 ~6 minecraft:dark_oak_planks
setblock ~7 ~36 ~7 minecraft:dark_oak_planks
setblock ~7 ~36 ~16 minecraft:dark_oak_planks
setblock ~7 ~36 ~17 minecraft:dark_oak_planks
setblock ~7 ~36 ~18 minecraft:dark_oak_planks
setblock ~7 ~37 ~7 minecraft:dark_oak_planks
setblock ~7 ~37 ~8 minecraft:dark_oak_planks
setblock ~7 ~37 ~9 minecraft:dark_oak_planks
setblock ~7 ~37 ~15 minecraft:dark_oak_planks
setblock ~7 ~37 ~16 minecraft:dark_oak_planks
setblock ~7 ~37 ~17 minecraft:dark_oak_planks
setblock ~7 ~38 ~8 minecraft:dark_oak_planks
setblock ~7 ~38 ~9 minecraft:dark_oak_planks
setblock ~7 ~38 ~10 minecraft:dark_oak_planks
setblock ~7 ~38 ~13 minecraft:dark_oak_planks
setblock ~7 ~38 ~14 minecraft:dark_oak_planks
setblock ~7 ~38 ~15 minecraft:dark_oak_planks
setblock ~7 ~38 ~16 minecraft:dark_oak_planks
setblock ~7 ~39 ~9 minecraft:dark_oak_planks
setblock ~7 ~39 ~10 minecraft:dark_oak_planks
setblock ~7 ~39 ~11 minecraft:dark_oak_planks
setblock ~7 ~39 ~12 minecraft:dark_oak_planks
setblock ~7 ~39 ~13 minecraft:dark_oak_planks
setblock ~7 ~39 ~14 minecraft:dark_oak_planks
setblock ~7 ~39 ~15 minecraft:dark_oak_planks
setblock ~7 ~40 ~10 minecraft:dark_oak_planks
setblock ~7 ~40 ~11 minecraft:dark_oak_planks
setblock ~7 ~40 ~12 minecraft:dark_oak_planks
setblock ~7 ~40 ~13 minecraft:dark_oak_planks
setblock ~7 ~40 ~14 minecraft:dark_oak_planks
setblock ~8 ~0 ~2 minecraft:mossy_cobblestone
setblock ~8 ~0 ~12 minecraft:cobblestone
setblock ~8 ~0 ~13 minecraft:mossy_cobblestone
setblock ~8 ~0 ~14 minecraft:mossy_cobblestone
setblock ~8 ~0 ~21 minecraft:mossy_cobblestone
setblock ~8 ~0 ~22 minecraft:mossy_cobblestone
setblock ~8 ~1 ~2 minecraft:mossy_cobblestone
setblock ~8 ~1 ~3 minecraft:mossy_cobblestone
setblock ~8 ~1 ~12 minecraft:mossy_cobblestone
setblock ~8 ~1 ~13 minecraft:cobblestone
setblock ~8 ~1 ~14 minecraft:mossy_cobblestone
setblock ~8 ~1 ~21 minecraft:mossy_cobblestone
setblock ~8 ~1 ~22 minecraft:oak_leaves[distance=7,persistent=true]
setblock ~8 ~2 ~2 minecraft:mossy_cobblestone
setblock ~8 ~2 ~3 minecraft:mossy_cobblestone
setblock ~8 ~2 ~12 minecraft:cobblestone
setblock ~8 ~2 ~13 minecraft:stone_bricks
setblock ~8 ~2 ~14 minecraft:mossy_stone_bricks
setblock ~8 ~2 ~21 minecraft:oak_leaves[distance=7,persistent=true]
setblock ~8 ~2 ~22 minecraft:oak_leaves[distance=7,persistent=true]
setblock ~8 ~3 ~3 minecraft:cobblestone
setblock ~8 ~3 ~12 minecraft:cobblestone
setblock ~8 ~3 ~13 minecraft:mossy_stone_bricks
setblock ~8 ~3 ~14 minecraft:mossy_cobblestone
setblock ~8 ~3 ~20 minecraft:mossy_cobblestone
setblock ~8 ~3 ~21 minecraft:cobblestone
setblock ~8 ~4 ~3 minecraft:stone_bricks
setblock ~8 ~4 ~12 minecraft:mossy_cobblestone
setblock ~8 ~4 ~13 minecraft:mossy_stone_bricks
setblock ~8 ~4 ~14 minecraft:mossy_cobblestone
setblock ~8 ~4 ~20 minecraft:cobblestone
setblock ~8 ~4 ~21 minecraft:cobblestone
setblock ~8 ~5 ~2 minecraft:cobblestone
setblock ~8 ~5 ~3 minecraft:cobblestone
setblock ~8 ~5 ~4 minecraft:mossy_cobblestone
setblock ~8 ~5 ~12 minecraft:cobblestone
setblock ~8 ~5 ~13 minecraft:mossy_cobblestone
setblock ~8 ~5 ~14 minecraft:cobblestone
setblock ~8 ~5 ~20 minecraft:mossy_cobblestone
setblock ~8 ~5 ~21 minecraft:cobblestone
setblock ~8 ~5 ~22 minecraft:cobblestone
setblock ~8 ~6 ~2 minecraft:cobblestone
setblock ~8 ~6 ~3 minecraft:oak_leaves[distance=7,persistent=true]
setblock ~8 ~6 ~4 minecraft:cobblestone
setblock ~8 ~6 ~12 minecraft:mossy_cobblestone
setblock ~8 ~6 ~13 minecraft:cobblestone
setblock ~8 ~6 ~14 minecraft:mossy_cobblestone
setblock ~8 ~6 ~20 minecraft:mossy_cobblestone
setblock ~8 ~6 ~21 minecraft:oak_leaves[distance=7,persistent=true]
setblock ~8 ~6 ~22 minecraft:mossy_cobblestone
setblock ~8 ~7 ~3 minecraft:oak_leaves[distance=7,persistent=true]
setblock ~8 ~7 ~4 minecraft:cobblestone
setblock ~8 ~7 ~12 minecraft:mossy_cobblestone
setblock ~8 ~7 ~13 minecraft:cracked_stone_bricks
setblock ~8 ~7 ~14 minecraft:cobblestone
setblock ~8 ~7 ~20 minecraft:mossy_cobblestone
setblock ~8 ~7 ~21 minecraft:oak_leaves[distance=7,persistent=true]
setblock ~8 ~8 ~3 minecraft:oak_leaves[distance=7,persistent=true]
setblock ~8 ~8 ~4 minecraft:stone_bricks
setblock ~8 ~8 ~20 minecraft:cracked_stone_bricks
setblock ~8 ~8 ~21 minecraft:oak_leaves[distance=7,persistent=true]
setblock ~8 ~9 ~2 minecraft:mossy_cobblestone
setblock ~8 ~9 ~3 minecraft:cobblestone
setblock ~8 ~9 ~4 minecraft:mossy_cobblestone
setblock ~8 ~9 ~20 minecraft:cobblestone
setblock ~8 ~9 ~21 minecraft:oak_leaves[distance=7,persistent=true]
setblock ~8 ~10 ~2 minecraft:mossy_cobblestone
setblock ~8 ~10 ~3 minecraft:mossy_cobblestone
setblock ~8 ~10 ~4 minecraft:cobblestone
setblock ~8 ~10 ~20 minecraft:cobblestone
setblock ~8 ~10 ~21 minecraft:oak_leaves[distance=7,persistent=true]
setblock ~8 ~10 ~22 minecraft:oak_leaves[distance=7,persistent=true]
setblock ~8 ~11 ~3 minecraft:polished_blackstone
setblock ~8 ~11 ~4 minecraft:polished_blackstone
setblock ~8 ~11 ~20 minecraft:polished_blackstone
setblock ~8 ~11 ~21 minecraft:polished_blackstone
setblock ~8 ~12 ~2 minecraft:cobblestone
setblock ~8 ~12 ~3 minecraft:cobblestone
setblock ~8 ~12 ~4 minecraft:cracked_stone_bricks
setblock ~8 ~12 ~20 minecraft:cobblestone
setblock ~8 ~12 ~21 minecraft:mossy_cobblestone
setblock ~8 ~13 ~2 minecraft:cobblestone
setblock ~8 ~13 ~3 minecraft:polished_blackstone
setblock ~8 ~13 ~4 minecraft:polished_blackstone
setblock ~8 ~13 ~20 minecraft:polished_blackstone
setblock ~8 ~13 ~21 minecraft:cobblestone
setblock ~8 ~14 ~3 minecraft:polished_blackstone
setblock ~8 ~14 ~4 minecraft:cobblestone
setblock ~8 ~14 ~19 minecraft:cobblestone
setblock ~8 ~14 ~20 minecraft:cobblestone
setblock ~8 ~14 ~21 minecraft:cobblestone
setblock ~8 ~14 ~22 minecraft:cobblestone
setblock ~8 ~15 ~3 minecraft:cracked_stone_bricks
setblock ~8 ~15 ~4 minecraft:cobblestone
setblock ~8 ~15 ~20 minecraft:cobblestone
setblock ~8 ~15 ~21 minecraft:mossy_stone_bricks
setblock ~8 ~16 ~3 minecraft:cobblestone
setblock ~8 ~16 ~4 minecraft:cobblestone
setblock ~8 ~16 ~20 minecraft:cobblestone
setblock ~8 ~17 ~3 minecraft:cobblestone
setblock ~8 ~17 ~4 minecraft:cobblestone
setblock ~8 ~17 ~20 minecraft:cobblestone
setblock ~8 ~18 ~3 minecraft:cobblestone
setblock ~8 ~18 ~4 minecraft:cobblestone
setblock ~8 ~18 ~19 minecraft:cobblestone
setblock ~8 ~18 ~20 minecraft:stone_bricks
setblock ~8 ~19 ~4 minecraft:cobblestone
setblock ~8 ~19 ~19 minecraft:cobblestone
setblock ~8 ~19 ~20 minecraft:cobblestone
setblock ~8 ~20 ~4 minecraft:mossy_stone_bricks
setblock ~8 ~20 ~20 minecraft:cobblestone
setblock ~8 ~21 ~3 minecraft:stone_bricks
setblock ~8 ~21 ~4 minecraft:polished_blackstone
setblock ~8 ~21 ~20 minecraft:polished_blackstone
setblock ~8 ~21 ~21 minecraft:cobblestone
setblock ~8 ~22 ~3 minecraft:cobblestone
setblock ~8 ~22 ~4 minecraft:stone_bricks
setblock ~8 ~22 ~20 minecraft:stone_bricks
setblock ~8 ~22 ~21 minecraft:cobblestone
setblock ~8 ~23 ~2 minecraft:cobblestone
setblock ~8 ~23 ~3 minecraft:cobblestone
setblock ~8 ~23 ~4 minecraft:cobblestone
setblock ~8 ~23 ~5 minecraft:cobblestone
setblock ~8 ~23 ~19 minecraft:cobblestone
setblock ~8 ~23 ~20 minecraft:cobblestone
setblock ~8 ~23 ~21 minecraft:cobblestone
setblock ~8 ~24 ~3 minecraft:cobblestone
setblock ~8 ~24 ~4 minecraft:cobblestone
setblock ~8 ~24 ~5 minecraft:cobblestone
setblock ~8 ~24 ~19 minecraft:cobblestone
setblock ~8 ~24 ~20 minecraft:stone_bricks
setblock ~8 ~24 ~21 minecraft:cobblestone
setblock ~8 ~25 ~4 minecraft:cracked_stone_bricks
setblock ~8 ~25 ~5 minecraft:cobblestone
setblock ~8 ~25 ~19 minecraft:stone_bricks
setblock ~8 ~25 ~20 minecraft:cobblestone
setblock ~8 ~26 ~4 minecraft:cobblestone
setblock ~8 ~26 ~5 minecraft:cobblestone
setblock ~8 ~26 ~19 minecraft:stone_bricks
setblock ~8 ~26 ~20 minecraft:cobblestone
setblock ~8 ~27 ~4 minecraft:cobblestone
setblock ~8 ~27 ~5 minecraft:cobblestone
setblock ~8 ~27 ~19 minecraft:cobblestone
setblock ~8 ~27 ~20 minecraft:cracked_stone_bricks
setblock ~8 ~28 ~4 minecraft:stone_bricks
setblock ~8 ~28 ~5 minecraft:cobblestone
setblock ~8 ~28 ~19 minecraft:cobblestone
setblock ~8 ~28 ~20 minecraft:stone_bricks
setblock ~8 ~29 ~4 minecraft:polished_blackstone
setblock ~8 ~29 ~5 minecraft:polished_blackstone
setblock ~8 ~29 ~19 minecraft:polished_blackstone
setblock ~8 ~29 ~20 minecraft:polished_blackstone
setblock ~8 ~30 ~2 minecraft:spruce_planks
setblock ~8 ~30 ~3 minecraft:cobblestone
setblock ~8 ~30 ~4 minecraft:cracked_stone_bricks
setblock ~8 ~30 ~5 minecraft:cobblestone
setblock ~8 ~30 ~19 minecraft:cobblestone
setblock ~8 ~30 ~20 minecraft:cobblestone
setblock ~8 ~30 ~21 minecraft:cobblestone
setblock ~8 ~30 ~22 minecraft:spruce_planks
setblock ~8 ~31 ~1 minecraft:dark_oak_planks
setblock ~8 ~31 ~2 minecraft:dark_oak_planks
setblock ~8 ~31 ~3 minecraft:dark_oak_planks
setblock ~8 ~31 ~4 minecraft:dark_oak_planks
setblock ~8 ~31 ~5 minecraft:dark_oak_planks
setblock ~8 ~31 ~19 minecraft:dark_oak_planks
setblock ~8 ~31 ~20 minecraft:dark_oak_planks
setblock ~8 ~31 ~21 minecraft:dark_oak_planks
setblock ~8 ~31 ~22 minecraft:dark_oak_planks
setblock ~8 ~32 ~2 minecraft:dark_oak_planks
setblock ~8 ~32 ~3 minecraft:dark_oak_planks
setblock ~8 ~32 ~21 minecraft:dark_oak_planks
setblock ~8 ~32 ~22 minecraft:dark_oak_planks
setblock ~8 ~33 ~3 minecraft:dark_oak_planks
setblock ~8 ~33 ~4 minecraft:dark_oak_planks
setblock ~8 ~33 ~20 minecraft:dark_oak_planks
setblock ~8 ~33 ~21 minecraft:dark_oak_planks
setblock ~8 ~34 ~4 minecraft:dark_oak_planks
setblock ~8 ~34 ~5 minecraft:dark_oak_planks
setblock ~8 ~34 ~19 minecraft:dark_oak_planks
setblock ~8 ~34 ~20 minecraft:dark_oak_planks
setblock ~8 ~35 ~5 minecraft:dark_oak_planks
setblock ~8 ~35 ~6 minecraft:dark_oak_planks
setblock ~8 ~35 ~18 minecraft:dark_oak_planks
setblock ~8 ~35 ~19 minecraft:dark_oak_planks
setblock ~8 ~36 ~5 minecraft:dark_oak_planks
setblock ~8 ~36 ~6 minecraft:dark_oak_planks
setblock ~8 ~36 ~7 minecraft:dark_oak_planks
setblock ~8 ~36 ~17 minecraft:dark_oak_planks
setblock ~8 ~36 ~18 minecraft:dark_oak_planks
setblock ~8 ~37 ~6 minecraft:dark_oak_planks
setblock ~8 ~37 ~7 minecraft:dark_oak_planks
setblock ~8 ~37 ~8 minecraft:dark_oak_planks
setblock ~8 ~37 ~16 minecraft:dark_oak_planks
setblock ~8 ~37 ~17 minecraft:dark_oak_planks
setblock ~8 ~38 ~7 minecraft:dark_oak_planks
setblock ~8 ~38 ~8 minecraft:dark_oak_planks
setblock ~8 ~38 ~9 minecraft:dark_oak_planks
setblock ~8 ~38 ~15 minecraft:dark_oak_planks
setblock ~8 ~38 ~16 minecraft:dark_oak_planks
setblock ~8 ~38 ~17 minecraft:dark_oak_planks
setblock ~8 ~39 ~8 minecraft:dark_oak_planks
setblock ~8 ~39 ~9 minecraft:dark_oak_planks
setblock ~8 ~39 ~10 minecraft:dark_oak_planks
setblock ~8 ~39 ~13 minecraft:dark_oak_planks
setblock ~8 ~39 ~14 minecraft:dark_oak_planks
setblock ~8 ~39 ~15 minecraft:dark_oak_planks
setblock ~8 ~39 ~16 minecraft:dark_oak_planks
setblock ~8 ~40 ~9 minecraft:dark_oak_planks
setblock ~8 ~40 ~10 minecraft:dark_oak_planks
setblock ~8 ~40 ~11 minecraft:dark_oak_planks
setblock ~8 ~40 ~12 minecraft:dark_oak_planks
setblock ~8 ~40 ~13 minecraft:dark_oak_planks
setblock ~8 ~40 ~14 minecraft:dark_oak_planks
setblock ~8 ~40 ~15 minecraft:dark_oak_planks
setblock ~8 ~41 ~10 minecraft:dark_oak_planks
setblock ~8 ~41 ~11 minecraft:dark_oak_planks
setblock ~8 ~41 ~12 minecraft:dark_oak_planks
setblock ~8 ~41 ~13 minecraft:dark_oak_planks
setblock ~8 ~41 ~14 minecraft:dark_oak_planks
setblock ~8 ~42 ~12 minecraft:dark_oak_planks
setblock ~9 ~0 ~2 minecraft:mossy_cobblestone
setblock ~9 ~0 ~12 minecraft:mossy_cobblestone
setblock ~9 ~0 ~13 minecraft:mossy_cobblestone
setblock ~9 ~0 ~14 minecraft:mossy_cobblestone
setblock ~9 ~0 ~22 minecraft:oak_leaves[distance=7,persistent=true]
setblock ~9 ~1 ~1 minecraft:oak_leaves[distance=7,persistent=true]
setblock ~9 ~1 ~2 minecraft:oak_leaves[distance=7,persistent=true]
setblock ~9 ~1 ~3 minecraft:oak_leaves[distance=7,persistent=true]
setblock ~9 ~1 ~12 minecraft:mossy_cobblestone
setblock ~9 ~1 ~13 minecraft:stone_bricks
setblock ~9 ~1 ~14 minecraft:cobblestone
setblock ~9 ~1 ~21 minecraft:mossy_cobblestone
setblock ~9 ~1 ~22 minecraft:oak_leaves[distance=7,persistent=true]
setblock ~9 ~2 ~2 minecraft:oak_leaves[distance=7,persistent=true]
setblock ~9 ~2 ~3 minecraft:mossy_cobblestone
setblock ~9 ~2 ~12 minecraft:mossy_cobblestone
setblock ~9 ~2 ~13 minecraft:mossy_cobblestone
setblock ~9 ~2 ~14 minecraft:mossy_cobblestone
setblock ~9 ~2 ~21 minecraft:mossy_cobblestone
setblock ~9 ~2 ~22 minecraft:oak_leaves[distance=7,persistent=true]
setblock ~9 ~3 ~2 minecraft:oak_leaves[distance=7,persistent=true]
setblock ~9 ~3 ~3 minecraft:mossy_cobblestone
setblock ~9 ~3 ~12 minecraft:cracked_stone_bricks
setblock ~9 ~3 ~13 minecraft:mossy_cobblestone
setblock ~9 ~3 ~14 minecraft:mossy_cobblestone
setblock ~9 ~3 ~21 minecraft:mossy_cobblestone
setblock ~9 ~4 ~2 minecraft:oak_leaves[distance=7,persistent=true]
setblock ~9 ~4 ~3 minecraft:mossy_cobblestone
setblock ~9 ~4 ~12 minecraft:mossy_cobblestone
setblock ~9 ~4 ~13 minecraft:mossy_cobblestone
setblock ~9 ~4 ~14 minecraft:cobblestone
setblock ~9 ~4 ~21 minecraft:mossy_cobblestone
setblock ~9 ~5 ~2 minecraft:cobblestone
setblock ~9 ~5 ~3 minecraft:cobblestone
setblock ~9 ~5 ~4 minecraft:mossy_cobblestone
setblock ~9 ~5 ~12 minecraft:mossy_cobblestone
setblock ~9 ~5 ~13 minecraft:stone_bricks
setblock ~9 ~5 ~14 minecraft:stone_bricks
setblock ~9 ~5 ~20 minecraft:cracked_stone_bricks
setblock ~9 ~5 ~21 minecraft:mossy_cobblestone
setblock ~9 ~6 ~2 minecraft:oak_leaves[distance=7,persistent=true]
setblock ~9 ~6 ~3 minecraft:oak_leaves[distance=7,persistent=true]
setblock ~9 ~6 ~13 minecraft:mossy_cobblestone
setblock ~9 ~6 ~14 minecraft:cobblestone
setblock ~9 ~6 ~20 minecraft:mossy_cobblestone
setblock ~9 ~6 ~21 minecraft:mossy_cobblestone
setblock ~9 ~7 ~3 minecraft:oak_leaves[distance=7,persistent=true]
setblock ~9 ~7 ~12 minecraft:cobblestone
setblock ~9 ~7 ~13 minecraft:mossy_cobblestone
setblock ~9 ~7 ~14 minecraft:mossy_cobblestone
setblock ~9 ~7 ~20 minecraft:cobblestone
setblock ~9 ~7 ~21 minecraft:cracked_stone_bricks
setblock ~9 ~8 ~13 minecraft:cobblestone
setblock ~9 ~8 ~14 minecraft:mossy_stone_bricks
setblock ~9 ~8 ~20 minecraft:mossy_stone_bricks
setblock ~9 ~8 ~21 minecraft:mossy_cobblestone
setblock ~9 ~9 ~2 minecraft:cobblestone
setblock ~9 ~9 ~3 minecraft:cobblestone
setblock ~9 ~9 ~20 minecraft:cobblestone
setblock ~9 ~9 ~21 minecraft:mossy_stone_bricks
setblock ~9 ~10 ~2 minecraft:stone_bricks
setblock ~9 ~10 ~3 minecraft:cobblestone
setblock ~9 ~10 ~4 minecraft:mossy_cobblestone
setblock ~9 ~10 ~20 minecraft:mossy_cobblestone
setblock ~9 ~10 ~21 minecraft:stone_bricks
setblock ~9 ~11 ~3 minecraft:polished_blackstone
setblock ~9 ~11 ~4 minecraft:polished_blackstone
setblock ~9 ~11 ~20 minecraft:polished_blackstone
setblock ~9 ~11 ~21 minecraft:polished_blackstone
setblock ~9 ~12 ~2 minecraft:cracked_stone_bricks
setblock ~9 ~12 ~3 minecraft:polished_blackstone
setblock ~9 ~12 ~4 minecraft:cobblestone
setblock ~9 ~12 ~20 minecraft:cobblestone
setblock ~9 ~12 ~21 minecraft:cracked_stone_bricks
setblock ~9 ~12 ~22 minecraft:cobblestone
setblock ~9 ~13 ~2 minecraft:cobblestone
setblock ~9 ~13 ~3 minecraft:polished_blackstone
setblock ~9 ~13 ~4 minecraft:polished_blackstone
setblock ~9 ~13 ~20 minecraft:polished_blackstone
setblock ~9 ~13 ~21 minecraft:polished_blackstone
setblock ~9 ~14 ~3 minecraft:cobblestone
setblock ~9 ~14 ~4 minecraft:cobblestone
setblock ~9 ~14 ~20 minecraft:cobblestone
setblock ~9 ~14 ~21 minecraft:cobblestone
setblock ~9 ~14 ~22 minecraft:cobblestone
setblock ~9 ~15 ~3 minecraft:cobblestone
setblock ~9 ~15 ~4 minecraft:cobblestone
setblock ~9 ~15 ~20 minecraft:stone_bricks
setblock ~9 ~15 ~21 minecraft:cobblestone
setblock ~9 ~16 ~3 minecraft:cobblestone
setblock ~9 ~16 ~4 minecraft:stone_bricks
setblock ~9 ~17 ~3 minecraft:cobblestone
setblock ~9 ~17 ~4 minecraft:stone_bricks
setblock ~9 ~18 ~3 minecraft:cobblestone
setblock ~9 ~18 ~4 minecraft:cobblestone
setblock ~9 ~19 ~3 minecraft:cobblestone
setblock ~9 ~19 ~4 minecraft:cobblestone
setblock ~9 ~19 ~20 minecraft:cobblestone
setblock ~9 ~20 ~3 minecraft:polished_blackstone
setblock ~9 ~20 ~4 minecraft:cobblestone
setblock ~9 ~20 ~20 minecraft:cobblestone
setblock ~9 ~20 ~21 minecraft:stone_bricks
setblock ~9 ~21 ~3 minecraft:polished_blackstone
setblock ~9 ~21 ~4 minecraft:polished_blackstone
setblock ~9 ~21 ~20 minecraft:polished_blackstone
setblock ~9 ~21 ~21 minecraft:stone_bricks
setblock ~9 ~22 ~3 minecraft:cobblestone
setblock ~9 ~22 ~4 minecraft:cobblestone
setblock ~9 ~22 ~20 minecraft:cobblestone
setblock ~9 ~22 ~21 minecraft:cobblestone
setblock ~9 ~23 ~2 minecraft:cobblestone
setblock ~9 ~23 ~3 minecraft:stone_bricks
setblock ~9 ~23 ~4 minecraft:cobblestone
setblock ~9 ~23 ~5 minecraft:cobblestone
setblock ~9 ~23 ~19 minecraft:cobblestone
setblock ~9 ~23 ~20 minecraft:stone_bricks
setblock ~9 ~23 ~21 minecraft:stone_bricks
setblock ~9 ~24 ~3 minecraft:cobblestone
setblock ~9 ~24 ~4 minecraft:cobblestone
setblock ~9 ~24 ~19 minecraft:cobblestone
setblock ~9 ~24 ~20 minecraft:cracked_stone_bricks
setblock ~9 ~24 ~21 minecraft:stone_bricks
setblock ~9 ~25 ~19 minecraft:mossy_stone_bricks
setblock ~9 ~27 ~19 minecraft:cobblestone
setblock ~9 ~28 ~3 minecraft:cobblestone
setblock ~9 ~28 ~4 minecraft:cobblestone
setblock ~9 ~28 ~5 minecraft:cobblestone
setblock ~9 ~28 ~19 minecraft:stone_bricks
setblock ~9 ~28 ~20 minecraft:cobblestone
setblock ~9 ~28 ~21 minecraft:cracked_stone_bricks
setblock ~9 ~29 ~3 minecraft:cobblestone
setblock ~9 ~29 ~4 minecraft:polished_blackstone
setblock ~9 ~29 ~5 minecraft:cracked_stone_bricks
setblock ~9 ~29 ~19 minecraft:polished_blackstone
setblock ~9 ~29 ~20 minecraft:polished_blackstone
setblock ~9 ~29 ~21 minecraft:cobblestone
setblock ~9 ~30 ~2 minecraft:spruce_planks
setblock ~9 ~30 ~3 minecraft:cracked_stone_bricks
setblock ~9 ~30 ~4 minecraft:cobblestone
setblock ~9 ~30 ~5 minecraft:spruce_planks
setblock ~9 ~30 ~19 minecraft:cobblestone
setblock ~9 ~30 ~20 minecraft:cobblestone
setblock ~9 ~30 ~21 minecraft:cobblestone
setblock ~9 ~30 ~22 minecraft:spruce_planks
setblock ~9 ~31 ~1 minecraft:dark_oak_planks
setblock ~9 ~31 ~2 minecraft:dark_oak_planks
setblock ~9 ~31 ~3 minecraft:dark_oak_planks
setblock ~9 ~31 ~4 minecraft:dark_oak_planks
setblock ~9 ~31 ~5 minecraft:dark_oak_planks
setblock ~9 ~31 ~19 minecraft:dark_oak_planks
setblock ~9 ~31 ~20 minecraft:dark_oak_planks
setblock ~9 ~31 ~21 minecraft:dark_oak_planks
setblock ~9 ~31 ~22 minecraft:dark_oak_planks
setblock ~9 ~32 ~2 minecraft:dark_oak_planks
setblock ~9 ~32 ~3 minecraft:dark_oak_planks
setblock ~9 ~32 ~21 minecraft:dark_oak_planks
setblock ~9 ~32 ~22 minecraft:dark_oak_planks
setblock ~9 ~33 ~3 minecraft:dark_oak_planks
setblock ~9 ~33 ~4 minecraft:dark_oak_planks
setblock ~9 ~33 ~20 minecraft:dark_oak_planks
setblock ~9 ~33 ~21 minecraft:dark_oak_planks
setblock ~9 ~34 ~3 minecraft:dark_oak_planks
setblock ~9 ~34 ~4 minecraft:dark_oak_planks
setblock ~9 ~34 ~5 minecraft:dark_oak_planks
setblock ~9 ~34 ~19 minecraft:dark_oak_planks
setblock ~9 ~34 ~20 minecraft:dark_oak_planks
setblock ~9 ~35 ~4 minecraft:dark_oak_planks
setblock ~9 ~35 ~5 minecraft:dark_oak_planks
setblock ~9 ~35 ~6 minecraft:dark_oak_planks
setblock ~9 ~35 ~18 minecraft:dark_oak_planks
setblock ~9 ~35 ~19 minecraft:dark_oak_planks
setblock ~9 ~36 ~5 minecraft:dark_oak_planks
setblock ~9 ~36 ~6 minecraft:dark_oak_planks
setblock ~9 ~36 ~7 minecraft:dark_oak_planks
setblock ~9 ~36 ~17 minecraft:dark_oak_planks
setblock ~9 ~36 ~18 minecraft:dark_oak_planks
setblock ~9 ~36 ~19 minecraft:dark_oak_planks
setblock ~9 ~37 ~6 minecraft:dark_oak_planks
setblock ~9 ~37 ~7 minecraft:dark_oak_planks
setblock ~9 ~37 ~16 minecraft:dark_oak_planks
setblock ~9 ~37 ~17 minecraft:dark_oak_planks
setblock ~9 ~37 ~18 minecraft:dark_oak_planks
setblock ~9 ~38 ~7 minecraft:dark_oak_planks
setblock ~9 ~38 ~8 minecraft:dark_oak_planks
setblock ~9 ~38 ~15 minecraft:dark_oak_planks
setblock ~9 ~38 ~16 minecraft:dark_oak_planks
setblock ~9 ~38 ~17 minecraft:dark_oak_planks
setblock ~9 ~39 ~8 minecraft:dark_oak_planks
setblock ~9 ~39 ~9 minecraft:dark_oak_planks
setblock ~9 ~39 ~14 minecraft:dark_oak_planks
setblock ~9 ~39 ~15 minecraft:dark_oak_planks
setblock ~9 ~39 ~16 minecraft:dark_oak_planks
setblock ~9 ~40 ~9 minecraft:dark_oak_planks
setblock ~9 ~40 ~10 minecraft:dark_oak_planks
setblock ~9 ~40 ~13 minecraft:dark_oak_planks
setblock ~9 ~40 ~14 minecraft:dark_oak_planks
setblock ~9 ~40 ~15 minecraft:dark_oak_planks
setblock ~9 ~41 ~10 minecraft:dark_oak_planks
setblock ~9 ~41 ~11 minecraft:dark_oak_planks
setblock ~9 ~41 ~12 minecraft:dark_oak_planks
setblock ~9 ~41 ~13 minecraft:dark_oak_planks
setblock ~9 ~41 ~14 minecraft:dark_oak_planks
setblock ~9 ~42 ~11 minecraft:dark_oak_planks
setblock ~9 ~42 ~12 minecraft:dark_oak_planks
setblock ~9 ~42 ~13 minecraft:dark_oak_planks
setblock ~9 ~43 ~11 minecraft:dark_oak_planks
setblock ~9 ~43 ~12 minecraft:dark_oak_planks
setblock ~10 ~0 ~2 minecraft:mossy_cobblestone
setblock ~10 ~0 ~13 minecraft:mossy_cobblestone
setblock ~10 ~0 ~22 minecraft:cobblestone
setblock ~10 ~1 ~1 minecraft:oak_leaves[distance=7,persistent=true]
setblock ~10 ~1 ~2 minecraft:mossy_cobblestone
setblock ~10 ~1 ~13 minecraft:mossy_cobblestone
setblock ~10 ~1 ~21 minecraft:mossy_cobblestone
setblock ~10 ~1 ~22 minecraft:mossy_cobblestone
setblock ~10 ~2 ~2 minecraft:cobblestone
setblock ~10 ~2 ~3 minecraft:mossy_cobblestone
setblock ~10 ~2 ~13 minecraft:cracked_stone_bricks
setblock ~10 ~2 ~21 minecraft:mossy_cobblestone
setblock ~10 ~2 ~22 minecraft:cobblestone
setblock ~10 ~3 ~2 minecraft:oak_leaves[distance=7,persistent=true]
setblock ~10 ~3 ~3 minecraft:mossy_cobblestone
setblock ~10 ~3 ~12 minecraft:cobblestone
setblock ~10 ~3 ~13 minecraft:stone_bricks
setblock ~10 ~3 ~21 minecraft:mossy_cobblestone
setblock ~10 ~4 ~2 minecraft:oak_leaves[distance=7,persistent=true]
setblock ~10 ~4 ~3 minecraft:mossy_cobblestone
setblock ~10 ~4 ~12 minecraft:mossy_stone_bricks
setblock ~10 ~4 ~13 minecraft:mossy_cobblestone
setblock ~10 ~4 ~14 minecraft:mossy_cobblestone
setblock ~10 ~4 ~21 minecraft:mossy_cobblestone
setblock ~10 ~5 ~2 minecraft:cobblestone
setblock ~10 ~5 ~3 minecraft:mossy_cobblestone
setblock ~10 ~5 ~4 minecraft:cobblestone
setblock ~10 ~5 ~12 minecraft:mossy_cobblestone
setblock ~10 ~5 ~13 minecraft:cobblestone
setblock ~10 ~5 ~14 minecraft:mossy_cobblestone
setblock ~10 ~5 ~21 minecraft:mossy_cobblestone
setblock ~10 ~6 ~2 minecraft:cobblestone
setblock ~10 ~6 ~3 minecraft:oak_leaves[distance=7,persistent=true]
setblock ~10 ~6 ~4 minecraft:cobblestone
setblock ~10 ~6 ~13 minecraft:cobblestone
setblock ~10 ~6 ~21 minecraft:cobblestone
setblock ~10 ~7 ~3 minecraft:cracked_stone_bricks
setblock ~10 ~7 ~4 minecraft:mossy_cobblestone
setblock ~10 ~7 ~12 minecraft:cracked_stone_bricks
setblock ~10 ~7 ~13 minecraft:mossy_cobblestone
setblock ~10 ~7 ~14 minecraft:mossy_cobblestone
setblock ~10 ~7 ~20 minecraft:mossy_cobblestone
setblock ~10 ~7 ~21 minecraft:cobblestone
setblock ~10 ~8 ~4 minecraft:mossy_cobblestone
setblock ~10 ~8 ~12 minecraft:cobblestone
setblock ~10 ~8 ~13 minecraft:cobblestone
setblock ~10 ~8 ~14 minecraft:cobblestone
setblock ~10 ~8 ~20 minecraft:cobblestone
setblock ~10 ~8 ~21 minecraft:cobblestone
setblock ~10 ~9 ~3 minecraft:cracked_stone_bricks
setblock ~10 ~9 ~4 minecraft:stone_bricks
setblock ~10 ~9 ~20 minecraft:mossy_cobblestone
setblock ~10 ~9 ~21 minecraft:cobblestone
setblock ~10 ~10 ~3 minecraft:mossy_cobblestone
setblock ~10 ~10 ~4 minecraft:cobblestone
setblock ~10 ~10 ~20 minecraft:cobblestone
setblock ~10 ~10 ~21 minecraft:cobblestone
setblock ~10 ~11 ~3 minecraft:polished_blackstone
setblock ~10 ~11 ~20 minecraft:polished_blackstone
setblock ~10 ~11 ~21 minecraft:polished_blackstone
setblock ~10 ~12 ~2 minecraft:cobblestone
setblock ~10 ~12 ~3 minecraft:cobblestone
setblock ~10 ~12 ~4 minecraft:cobblestone
setblock ~10 ~12 ~20 minecraft:cobblestone
setblock ~10 ~12 ~21 minecraft:cobblestone
setblock ~10 ~12 ~22 minecraft:cobblestone
setblock ~10 ~13 ~2 minecraft:cobblestone
setblock ~10 ~13 ~3 minecraft:polished_blackstone
setblock ~10 ~13 ~4 minecraft:polished_blackstone
setblock ~10 ~13 ~20 minecraft:polished_blackstone
setblock ~10 ~13 ~21 minecraft:polished_blackstone
setblock ~10 ~13 ~22 minecraft:cobblestone
setblock ~10 ~14 ~3 minecraft:stone_bricks
setblock ~10 ~14 ~4 minecraft:cobblestone
